Workbook
Name Průřez_Trasa: #N/A

Sheet List1
C3: zastavky | G3: auta | H3: list auta | J3: nova tabulka spojeni
F4: ID | G4: Trasa | H4: beze zmeny | J4: zastavka ID | K4: ID z auta | L4: R | M4: O | N4: N
C5: 1 | D5: Kostel | F5: 1 | G5: tatra 1 | J5: 1 | K5: 1 | L5: 0.22916667 | M5: 0.58333333 | N5: 0.91666667
C6: 2 | D6: Benzinka | F6: 2 | G6: tatra 2 | J6: 2 | K6: 2 | L6: 0.22222222

Sheet zastavky
B1: ID | C1: Zastávka | D1: Sloupec1 | F1: Miasto (Město) | G1: Przystanek / Lokalizacja (Zastávka) | H1: Spolu
B2: 01 | C2: Cieszyn, Brama Myta (dawne przejście graniczne) | D2: =Tab_Zast[[#This Row],[ID]] -> 01 | F2: Cieszyn | G2: Brama Myta (dawne przejście graniczne) | H2: =F2&", "&G2 -> Cieszyn, Brama Myta (dawne przejście graniczne) | I2: ="insert into nastupy (zastavka) values ('" & H2 & "');" -> insert into nastupy (zastavka) values ('Cieszyn, Brama Myta (dawne przejście graniczne)');
B3: 02 | C3: Cieszyn, McDonald's | D3: =Tab_Zast[[#This Row],[ID]] -> 02 | F3: Cieszyn | G3: McDonalds | H3: =F3&", "&G3 -> Cieszyn, McDonalds | I3: ="insert into nastupy (zastavka) values ('" & H3 & "');" -> insert into nastupy (zastavka) values ('Cieszyn, McDonalds');
B4: 03 | C4: Cieszyn, ul. Katowicka (Cmentarz / Orlen / Biedronka) | D4: =Tab_Zast[[#This Row],[ID]] -> 03 | F4: Cieszyn | G4: ul. Katowicka (Cmentarz / Orlen / Biedronka) | H4: =F4&", "&G4 -> Cieszyn, ul. Katowicka (Cmentarz / Orlen / Biedronka) | I4: ="insert into nastupy (zastavka) values ('" & H4 & "');" -> insert into nastupy (zastavka) values ('Cieszyn, ul. Katowicka (Cmentarz / Orlen / Biedronka)');
B5: 04 | C5: Cieszyn, ul. Liburnia (Kaufland) | D5: =Tab_Zast[[#This Row],[ID]] -> 04 | F5: Cieszyn | G5: ul. Liburnia (Kaufland) | H5: =F5&", "&G5 -> Cieszyn, ul. Liburnia (Kaufland) | I5: ="insert into nastupy (zastavka) values ('" & H5 & "');" -> insert into nastupy (zastavka) values ('Cieszyn, ul. Liburnia (Kaufland)');
B6: 05 | C6: Cieszyn, ul. Liburnia (Kościół) | D6: =Tab_Zast[[#This Row],[ID]] -> 05 | F6: Cieszyn | G6: ul. Liburnia (Kościół) | H6: =F6&", "&G6 -> Cieszyn, ul. Liburnia (Kościół) | I6: ="insert into nastupy (zastavka) values ('" & H6 & "');" -> insert into nastupy (zastavka) values ('Cieszyn, ul. Liburnia (Kościół)');
B7: 06 | C7: Cieszyn, ul. Liburnia (Starostwo Powiatowe) | D7: =Tab_Zast[[#This Row],[ID]] -> 06 | F7: Cieszyn | G7: ul. Liburnia (Starostwo Powiatowe) | H7: =F7&", "&G7 -> Cieszyn, ul. Liburnia (Starostwo Powiatowe) | I7: ="insert into nastupy (zastavka) values ('" & H7 & "');" -> insert into nastupy (zastavka) values ('Cieszyn, ul. Liburnia (Starostwo Powiatowe)');
B8: 07 | C8: Cieszyn, ul. Liburnia (Warsztat) | D8: =Tab_Zast[[#This Row],[ID]] -> 07 | F8: Cieszyn | G8: ul. Liburnia (Warsztat) | H8: =F8&", "&G8 -> Cieszyn, ul. Liburnia (Warsztat) | I8: ="insert into nastupy (zastavka) values ('" & H8 & "');" -> insert into nastupy (zastavka) values ('Cieszyn, ul. Liburnia (Warsztat)');
B9: 08 | C9: Cieszyn, ul. Stawowa (Pastwiska) | D9: =Tab_Zast[[#This Row],[ID]] -> 08 | F9: Cieszyn | G9: ul. Stawowa (Pastwiska) | H9: =F9&", "&G9 -> Cieszyn, ul. Stawowa (Pastwiska) | I9: ="insert into nastupy (zastavka) values ('" & H9 & "');" -> insert into nastupy (zastavka) values ('Cieszyn, ul. Stawowa (Pastwiska)');
B10: 09 | C10: Frýdek-Místek (CZ), Stacja Benzina / KMJ | D10: =Tab_Zast[[#This Row],[ID]] -> 09 | F10: Frýdek-Místek (CZ) | G10: Stacja Benzina / KMJ | H10: =F10&", "&G10 -> Frýdek-Místek (CZ), Stacja Benzina / KMJ | I10: ="insert into nastupy (zastavka) values ('" & H10 & "');" -> insert into nastupy (zastavka) values ('Frýdek-Místek (CZ), Stacja Benzina / KMJ');
B11: 10 | C11: Gołkowice, ul. 1 Maja (Centrum) | D11: =Tab_Zast[[#This Row],[ID]] -> 10 | F11: Gołkowice | G11: ul. 1 Maja (Centrum) | H11: =F11&", "&G11 -> Gołkowice, ul. 1 Maja (Centrum) | I11: ="insert into nastupy (zastavka) values ('" & H11 & "');" -> insert into nastupy (zastavka) values ('Gołkowice, ul. 1 Maja (Centrum)');
B12: 11 | C12: Gorzyce, Urząd Gminy | D12: =Tab_Zast[[#This Row],[ID]] -> 11 | F12: Gorzyce | G12: Urząd Gminy | H12: =F12&", "&G12 -> Gorzyce, Urząd Gminy | I12: ="insert into nastupy (zastavka) values ('" & H12 & "');" -> insert into nastupy (zastavka) values ('Gorzyce, Urząd Gminy');
B13: 12 | C13: Gorzyczki, UNIWAR | D13: =Tab_Zast[[#This Row],[ID]] -> 12 | F13: Gorzyczki | G13: UNIWAR | H13: =F13&", "&G13 -> Gorzyczki, UNIWAR | I13: ="insert into nastupy (zastavka) values ('" & H13 & "');" -> insert into nastupy (zastavka) values ('Gorzyczki, UNIWAR');
... B109: 108 | C109: Wodzisław Śląski, Dworzec Autobusowy (Galeria Karuzela) | D109: =Tab_Zast[[#This Row],[ID]] -> 108 | F109: Wodzisław Śląski | G109: Dworzec Autobusowy (Galeria Karuzela) | H109: =F109&", "&G109 -> Wodzisław Śląski, Dworzec Autobusowy (Galeria Karuzela) | I109: ="insert into nastupy (zastavka) values ('" & H109 & "');" -> insert into nastupy (zastavka) values ('Wodzisław Śląski, Dworzec Autobusowy (Galeria Karuzela)');
B110: 109 | C110: Vlastní auto | D110: =Tab_Zast[[#This Row],[ID]] -> 109 | H110: =F110&", "&G110 -> ,
H112: =F112&", "&G112 -> ,
H113: =F113&", "&G113 -> ,
H114: =F114&", "&G114 -> ,
H115: =F115&", "&G115 -> ,
H116: =F116&", "&G116 -> ,
H117: =F117&", "&G117 -> ,
H118: =F118&", "&G118 -> ,
H119: =F119&", "&G119 -> ,
H120: =F120&", "&G120 -> ,

Sheet auta
B1: ID | C1: Trasa | D1: Popis
B2: 01 | C2: ALLIANCE LAUNDRY 3 | D2: TRASA 3
B3: 02 | C3: ALLIANCE LAUNDRY 4 | D3: TRASA 4, 1 BUS
B4: 03 | C4: BATZ 1 | D4: BATZ/KMJ/THERMA - JASTRZEBIE/WODZISLAW/OSTRAVA
B5: 04 | C5: BATZ 2 | D5: BATZ/KMJ/THERMA - ŽORY/CIESZYN
B6: 05 | C6: DSC 1 | D6: DSC/DONGHEE - RYBNIK/WODZISLAW
B7: 06 | C7: DSC 2 | D7: DSC/DONGHEE - ŽORY/JASTRZEBIE
B8: 07 | C8: GUZU 1 | D8: Universal ZORY-Jastrzebie, Wodzislaw, Cieszyn
B9: 08 | C9: HILITE 1 | D9: HILITE - RYBNIK/WODZISLAW
B10: 09 | C10: HILITE 2 | D10: HILITE - TRASA ŹORY/JASTRZEBIE ZDRÓJ
B11: 10 | C11: TATRA - ALS - SPRINT | D11: TATRA/ALS - ŽORY_JASTRZEBIE
B12: 11 | C12: TATRA METALURGIE | D12: CELÁ TRASA PL/CZ
B13: 12 | C13: Vlastní auto | D13: Vlastní auto

Sheet novatabulka
B2: zastavka | C2: trasa | D2: R | E2: O | F2: N
B3: 62 | C3: 23 | D3: 0.17708333 | E3: 0 | F3: 0 | I3: ="insert into trasy (zastavka,auto,R,O,N) values ('" & Tabulka4[[#This Row],[zastavka]] & "','" & Tabulka4[[#This Row],[trasa]] & "','" & HOUR(Tabulka4[[#This Row],[R]]) & ":" & MINUTE(Tabulka4[[#This Row],[R]]) & "','" & HOUR(Tabulka4[[#This Row],[O]]) & ":" & MINUTE(Tabulka4[[#This Row],[O]]) & "','" & HOUR(Tabulka4[[#This Row],[N]]) & ":" & MINUTE(Tabulka4[[#This Row],[N]]) & "');" -> insert into trasy (zastavka,auto,R,O,N) values ('62','23','4:15','0:0','0:0');
B4: 82 | C4: 23 | D4: 0.19444444 | E4: 0 | F4: 0 | I4: ="insert into trasy (zastavka,auto,R,O,N) values ('" & Tabulka4[[#This Row],[zastavka]] & "','" & Tabulka4[[#This Row],[trasa]] & "','" & HOUR(Tabulka4[[#This Row],[R]]) & ":" & MINUTE(Tabulka4[[#This Row],[R]]) & "','" & HOUR(Tabulka4[[#This Row],[O]]) & ":" & MINUTE(Tabulka4[[#This Row],[O]]) & "','" & HOUR(Tabulka4[[#This Row],[N]]) & ":" & MINUTE(Tabulka4[[#This Row],[N]]) & "');" -> insert into trasy (zastavka,auto,R,O,N) values ('82','23','4:40','0:0','0:0'); | T4: 01 | U4: ALLIANCE LAUNDRY 3 | V4: TRASA 3
B5: 48 | C5: 23 | D5: 0.19791667 | E5: 0 | F5: 0 | I5: ="insert into trasy (zastavka,auto,R,O,N) values ('" & Tabulka4[[#This Row],[zastavka]] & "','" & Tabulka4[[#This Row],[trasa]] & "','" & HOUR(Tabulka4[[#This Row],[R]]) & ":" & MINUTE(Tabulka4[[#This Row],[R]]) & "','" & HOUR(Tabulka4[[#This Row],[O]]) & ":" & MINUTE(Tabulka4[[#This Row],[O]]) & "','" & HOUR(Tabulka4[[#This Row],[N]]) & ":" & MINUTE(Tabulka4[[#This Row],[N]]) & "');" -> insert into trasy (zastavka,auto,R,O,N) values ('48','23','4:45','0:0','0:0'); | T5: 02 | U5: ALLIANCE LAUNDRY 4 | V5: TRASA 4, 1 BUS
B6: 101 | C6: 26 | D6: 0.16666667 | E6: 0 | F6: 0 | I6: ="insert into trasy (zastavka,auto,R,O,N) values ('" & Tabulka4[[#This Row],[zastavka]] & "','" & Tabulka4[[#This Row],[trasa]] & "','" & HOUR(Tabulka4[[#This Row],[R]]) & ":" & MINUTE(Tabulka4[[#This Row],[R]]) & "','" & HOUR(Tabulka4[[#This Row],[O]]) & ":" & MINUTE(Tabulka4[[#This Row],[O]]) & "','" & HOUR(Tabulka4[[#This Row],[N]]) & ":" & MINUTE(Tabulka4[[#This Row],[N]]) & "');" -> insert into trasy (zastavka,auto,R,O,N) values ('101','26','4:0','0:0','0:0'); | T6: 03 | U6: BATZ 1 | V6: BATZ/KMJ/THERMA - JASTRZEBIE/WODZISLAW/OSTRAVA
B7: 36 | C7: 26 | D7: 0.17361111 | E7: 0 | F7: 0 | I7: ="insert into trasy (zastavka,auto,R,O,N) values ('" & Tabulka4[[#This Row],[zastavka]] & "','" & Tabulka4[[#This Row],[trasa]] & "','" & HOUR(Tabulka4[[#This Row],[R]]) & ":" & MINUTE(Tabulka4[[#This Row],[R]]) & "','" & HOUR(Tabulka4[[#This Row],[O]]) & ":" & MINUTE(Tabulka4[[#This Row],[O]]) & "','" & HOUR(Tabulka4[[#This Row],[N]]) & ":" & MINUTE(Tabulka4[[#This Row],[N]]) & "');" -> insert into trasy (zastavka,auto,R,O,N) values ('36','26','4:10','0:0','0:0'); | T7: 04 | U7: BATZ 2 | V7: BATZ/KMJ/THERMA - ŽORY/CIESZYN
B8: 22 | C8: 26 | D8: 0.17708333 | E8: 0 | F8: 0 | I8: ="insert into trasy (zastavka,auto,R,O,N) values ('" & Tabulka4[[#This Row],[zastavka]] & "','" & Tabulka4[[#This Row],[trasa]] & "','" & HOUR(Tabulka4[[#This Row],[R]]) & ":" & MINUTE(Tabulka4[[#This Row],[R]]) & "','" & HOUR(Tabulka4[[#This Row],[O]]) & ":" & MINUTE(Tabulka4[[#This Row],[O]]) & "','" & HOUR(Tabulka4[[#This Row],[N]]) & ":" & MINUTE(Tabulka4[[#This Row],[N]]) & "');" -> insert into trasy (zastavka,auto,R,O,N) values ('22','26','4:15','0:0','0:0'); | T8: 05 | U8: DSC 1 | V8: DSC/DONGHEE - RYBNIK/WODZISLAW
B9: 25 | C9: 26 | D9: 0.17847222 | E9: 0 | F9: 0 | I9: ="insert into trasy (zastavka,auto,R,O,N) values ('" & Tabulka4[[#This Row],[zastavka]] & "','" & Tabulka4[[#This Row],[trasa]] & "','" & HOUR(Tabulka4[[#This Row],[R]]) & ":" & MINUTE(Tabulka4[[#This Row],[R]]) & "','" & HOUR(Tabulka4[[#This Row],[O]]) & ":" & MINUTE(Tabulka4[[#This Row],[O]]) & "','" & HOUR(Tabulka4[[#This Row],[N]]) & ":" & MINUTE(Tabulka4[[#This Row],[N]]) & "');" -> insert into trasy (zastavka,auto,R,O,N) values ('25','26','4:17','0:0','0:0'); | T9: 06 | U9: DSC 2 | V9: DSC/DONGHEE - ŽORY/JASTRZEBIE
B10: 18 | C10: 26 | D10: 0.17986111 | E10: 0 | F10: 0 | I10: ="insert into trasy (zastavka,auto,R,O,N) values ('" & Tabulka4[[#This Row],[zastavka]] & "','" & Tabulka4[[#This Row],[trasa]] & "','" & HOUR(Tabulka4[[#This Row],[R]]) & ":" & MINUTE(Tabulka4[[#This Row],[R]]) & "','" & HOUR(Tabulka4[[#This Row],[O]]) & ":" & MINUTE(Tabulka4[[#This Row],[O]]) & "','" & HOUR(Tabulka4[[#This Row],[N]]) & ":" & MINUTE(Tabulka4[[#This Row],[N]]) & "');" -> insert into trasy (zastavka,auto,R,O,N) values ('18','26','4:19','0:0','0:0'); | T10: 07 | U10: GUZU 1 | V10: Universal ZORY-Jastrzebie, Wodzislaw, Cieszyn
B11: 24 | C11: 26 | D11: 0.18125 | E11: 0 | F11: 0 | I11: ="insert into trasy (zastavka,auto,R,O,N) values ('" & Tabulka4[[#This Row],[zastavka]] & "','" & Tabulka4[[#This Row],[trasa]] & "','" & HOUR(Tabulka4[[#This Row],[R]]) & ":" & MINUTE(Tabulka4[[#This Row],[R]]) & "','" & HOUR(Tabulka4[[#This Row],[O]]) & ":" & MINUTE(Tabulka4[[#This Row],[O]]) & "','" & HOUR(Tabulka4[[#This Row],[N]]) & ":" & MINUTE(Tabulka4[[#This Row],[N]]) & "');" -> insert into trasy (zastavka,auto,R,O,N) values ('24','26','4:21','0:0','0:0'); | T11: 08 | U11: HILITE 1 | V11: HILITE - RYBNIK/WODZISLAW
B12: 41 | C12: 26 | D12: 0.18402778 | E12: 0 | F12: 0 | I12: ="insert into trasy (zastavka,auto,R,O,N) values ('" & Tabulka4[[#This Row],[zastavka]] & "','" & Tabulka4[[#This Row],[trasa]] & "','" & HOUR(Tabulka4[[#This Row],[R]]) & ":" & MINUTE(Tabulka4[[#This Row],[R]]) & "','" & HOUR(Tabulka4[[#This Row],[O]]) & ":" & MINUTE(Tabulka4[[#This Row],[O]]) & "','" & HOUR(Tabulka4[[#This Row],[N]]) & ":" & MINUTE(Tabulka4[[#This Row],[N]]) & "');" -> insert into trasy (zastavka,auto,R,O,N) values ('41','26','4:25','0:0','0:0'); | T12: 09 | U12: HILITE 2 | V12: HILITE - TRASA ŹORY/JASTRZEBIE ZDRÓJ
B13: 95 | C13: 26 | D13: 0.19444444 | E13: 0 | F13: 0 | I13: ="insert into trasy (zastavka,auto,R,O,N) values ('" & Tabulka4[[#This Row],[zastavka]] & "','" & Tabulka4[[#This Row],[trasa]] & "','" & HOUR(Tabulka4[[#This Row],[R]]) & ":" & MINUTE(Tabulka4[[#This Row],[R]]) & "','" & HOUR(Tabulka4[[#This Row],[O]]) & ":" & MINUTE(Tabulka4[[#This Row],[O]]) & "','" & HOUR(Tabulka4[[#This Row],[N]]) & ":" & MINUTE(Tabulka4[[#This Row],[N]]) & "');" -> insert into trasy (zastavka,auto,R,O,N) values ('95','26','4:40','0:0','0:0'); | T13: 10 | U13: TATRA - ALS - SPRINT | V13: TATRA/ALS - ŽORY_JASTRZEBIE
B14: 13 | C14: 26 | D14: 0.2 | E14: 0 | F14: 0 | I14: ="insert into trasy (zastavka,auto,R,O,N) values ('" & Tabulka4[[#This Row],[zastavka]] & "','" & Tabulka4[[#This Row],[trasa]] & "','" & HOUR(Tabulka4[[#This Row],[R]]) & ":" & MINUTE(Tabulka4[[#This Row],[R]]) & "','" & HOUR(Tabulka4[[#This Row],[O]]) & ":" & MINUTE(Tabulka4[[#This Row],[O]]) & "','" & HOUR(Tabulka4[[#This Row],[N]]) & ":" & MINUTE(Tabulka4[[#This Row],[N]]) & "');" -> insert into trasy (zastavka,auto,R,O,N) values ('13','26','4:48','0:0','0:0'); | T14: 11 | U14: TATRA METALURGIE | V14: CELÁ TRASA PL/CZ
B15: 03 | C15: 26 | D15: 0.20486111 | E15: 0 | F15: 0 | I15: ="insert into trasy (zastavka,auto,R,O,N) values ('" & Tabulka4[[#This Row],[zastavka]] & "','" & Tabulka4[[#This Row],[trasa]] & "','" & HOUR(Tabulka4[[#This Row],[R]]) & ":" & MINUTE(Tabulka4[[#This Row],[R]]) & "','" & HOUR(Tabulka4[[#This Row],[O]]) & ":" & MINUTE(Tabulka4[[#This Row],[O]]) & "','" & HOUR(Tabulka4[[#This Row],[N]]) & ":" & MINUTE(Tabulka4[[#This Row],[N]]) & "');" -> insert into trasy (zastavka,auto,R,O,N) values ('03','26','4:55','0:0','0:0'); | T15: 12 | U15: Vlastní auto | V15: Vlastní auto
B16: 06 | C16: 26 | D16: 0.20625 | E16: 0 | F16: 0 | I16: ="insert into trasy (zastavka,auto,R,O,N) values ('" & Tabulka4[[#This Row],[zastavka]] & "','" & Tabulka4[[#This Row],[trasa]] & "','" & HOUR(Tabulka4[[#This Row],[R]]) & ":" & MINUTE(Tabulka4[[#This Row],[R]]) & "','" & HOUR(Tabulka4[[#This Row],[O]]) & ":" & MINUTE(Tabulka4[[#This Row],[O]]) & "','" & HOUR(Tabulka4[[#This Row],[N]]) & ":" & MINUTE(Tabulka4[[#This Row],[N]]) & "');" -> insert into trasy (zastavka,auto,R,O,N) values ('06','26','4:57','0:0','0:0');
B17: 05 | C17: 26 | D17: 0.20833333 | E17: 0 | F17: 0 | I17: ="insert into trasy (zastavka,auto,R,O,N) values ('" & Tabulka4[[#This Row],[zastavka]] & "','" & Tabulka4[[#This Row],[trasa]] & "','" & HOUR(Tabulka4[[#This Row],[R]]) & ":" & MINUTE(Tabulka4[[#This Row],[R]]) & "','" & HOUR(Tabulka4[[#This Row],[O]]) & ":" & MINUTE(Tabulka4[[#This Row],[O]]) & "','" & HOUR(Tabulka4[[#This Row],[N]]) & ":" & MINUTE(Tabulka4[[#This Row],[N]]) & "');" -> insert into trasy (zastavka,auto,R,O,N) values ('05','26','5:0','0:0','0:0');
B18: 40 | C18: 01 | D18: 0.15972222 | E18: 0.49305556 | F18: 0.82638889 | I18: ="insert into trasy (zastavka,auto,R,O,N) values ('" & Tabulka4[[#This Row],[zastavka]] & "','" & Tabulka4[[#This Row],[trasa]] & "','" & HOUR(Tabulka4[[#This Row],[R]]) & ":" & MINUTE(Tabulka4[[#This Row],[R]]) & "','" & HOUR(Tabulka4[[#This Row],[O]]) & ":" & MINUTE(Tabulka4[[#This Row],[O]]) & "','" & HOUR(Tabulka4[[#This Row],[N]]) & ":" & MINUTE(Tabulka4[[#This Row],[N]]) & "');" -> insert into trasy (zastavka,auto,R,O,N) values ('40','01','3:50','11:50','19:50');
B19: 39 | C19: 01 | D19: 0.16111111 | E19: 0.49444444 | F19: 0.82777778 | I19: ="insert into trasy (zastavka,auto,R,O,N) values ('" & Tabulka4[[#This Row],[zastavka]] & "','" & Tabulka4[[#This Row],[trasa]] & "','" & HOUR(Tabulka4[[#This Row],[R]]) & ":" & MINUTE(Tabulka4[[#This Row],[R]]) & "','" & HOUR(Tabulka4[[#This Row],[O]]) & ":" & MINUTE(Tabulka4[[#This Row],[O]]) & "','" & HOUR(Tabulka4[[#This Row],[N]]) & ":" & MINUTE(Tabulka4[[#This Row],[N]]) & "');" -> insert into trasy (zastavka,auto,R,O,N) values ('39','01','3:52','11:52','19:52');
B20: 17 | C20: 01 | D20: 0.1625 | E20: 0.49583333 | F20: 0.82916667 | I20: ="insert into trasy (zastavka,auto,R,O,N) values ('" & Tabulka4[[#This Row],[zastavka]] & "','" & Tabulka4[[#This Row],[trasa]] & "','" & HOUR(Tabulka4[[#This Row],[R]]) & ":" & MINUTE(Tabulka4[[#This Row],[R]]) & "','" & HOUR(Tabulka4[[#This Row],[O]]) & ":" & MINUTE(Tabulka4[[#This Row],[O]]) & "','" & HOUR(Tabulka4[[#This Row],[N]]) & ":" & MINUTE(Tabulka4[[#This Row],[N]]) & "');" -> insert into trasy (zastavka,auto,R,O,N) values ('17','01','3:54','11:54','19:54');
B21: 22 | C21: 01 | D21: 0.16527778 | E21: 0.49861111 | F21: 0.83194444 | I21: ="insert into trasy (zastavka,auto,R,O,N) values ('" & Tabulka4[[#This Row],[zastavka]] & "','" & Tabulka4[[#This Row],[trasa]] & "','" & HOUR(Tabulka4[[#This Row],[R]]) & ":" & MINUTE(Tabulka4[[#This Row],[R]]) & "','" & HOUR(Tabulka4[[#This Row],[O]]) & ":" & MINUTE(Tabulka4[[#This Row],[O]]) & "','" & HOUR(Tabulka4[[#This Row],[N]]) & ":" & MINUTE(Tabulka4[[#This Row],[N]]) & "');" -> insert into trasy (zastavka,auto,R,O,N) values ('22','01','3:58','11:58','19:58');
B22: 25 | C22: 01 | D22: 0.16805556 | E22: 0.50138889 | F22: 0.83472222 | I22: ="insert into trasy (zastavka,auto,R,O,N) values ('" & Tabulka4[[#This Row],[zastavka]] & "','" & Tabulka4[[#This Row],[trasa]] & "','" & HOUR(Tabulka4[[#This Row],[R]]) & ":" & MINUTE(Tabulka4[[#This Row],[R]]) & "','" & HOUR(Tabulka4[[#This Row],[O]]) & ":" & MINUTE(Tabulka4[[#This Row],[O]]) & "','" & HOUR(Tabulka4[[#This Row],[N]]) & ":" & MINUTE(Tabulka4[[#This Row],[N]]) & "');" -> insert into trasy (zastavka,auto,R,O,N) values ('25','01','4:2','12:2','20:2');
B23: 24 | C23: 01 | D23: 0.16944444 | E23: 0.50277778 | F23: 0.83611111 | I23: ="insert into trasy (zastavka,auto,R,O,N) values ('" & Tabulka4[[#This Row],[zastavka]] & "','" & Tabulka4[[#This Row],[trasa]] & "','" & HOUR(Tabulka4[[#This Row],[R]]) & ":" & MINUTE(Tabulka4[[#This Row],[R]]) & "','" & HOUR(Tabulka4[[#This Row],[O]]) & ":" & MINUTE(Tabulka4[[#This Row],[O]]) & "','" & HOUR(Tabulka4[[#This Row],[N]]) & ":" & MINUTE(Tabulka4[[#This Row],[N]]) & "');" -> insert into trasy (zastavka,auto,R,O,N) values ('24','01','4:4','12:4','20:4');
B24: 16 | C24: 01 | D24: 0.17222222 | E24: 0.50555556 | F24: 0.83888889 | I24: ="insert into trasy (zastavka,auto,R,O,N) values ('" & Tabulka4[[#This Row],[zastavka]] & "','" & Tabulka4[[#This Row],[trasa]] & "','" & HOUR(Tabulka4[[#This Row],[R]]) & ":" & MINUTE(Tabulka4[[#This Row],[R]]) & "','" & HOUR(Tabulka4[[#This Row],[O]]) & ":" & MINUTE(Tabulka4[[#This Row],[O]]) & "','" & HOUR(Tabulka4[[#This Row],[N]]) & ":" & MINUTE(Tabulka4[[#This Row],[N]]) & "');" -> insert into trasy (zastavka,auto,R,O,N) values ('16','01','4:8','12:8','20:8');
B25: 27 | C25: 01 | D25: 0.17361111 | E25: 0.50694444 | F25: 0.84027778 | I25: ="insert into trasy (zastavka,auto,R,O,N) values ('" & Tabulka4[[#This Row],[zastavka]] & "','" & Tabulka4[[#This Row],[trasa]] & "','" & HOUR(Tabulka4[[#This Row],[R]]) & ":" & MINUTE(Tabulka4[[#This Row],[R]]) & "','" & HOUR(Tabulka4[[#This Row],[O]]) & ":" & MINUTE(Tabulka4[[#This Row],[O]]) & "','" & HOUR(Tabulka4[[#This Row],[N]]) & ":" & MINUTE(Tabulka4[[#This Row],[N]]) & "');" -> insert into trasy (zastavka,auto,R,O,N) values ('27','01','4:10','12:10','20:10');
B26: 26 | C26: 01 | D26: 0.17569444 | E26: 0.50902778 | F26: 0.84236111 | I26: ="insert into trasy (zastavka,auto,R,O,N) values ('" & Tabulka4[[#This Row],[zastavka]] & "','" & Tabulka4[[#This Row],[trasa]] & "','" & HOUR(Tabulka4[[#This Row],[R]]) & ":" & MINUTE(Tabulka4[[#This Row],[R]]) & "','" & HOUR(Tabulka4[[#This Row],[O]]) & ":" & MINUTE(Tabulka4[[#This Row],[O]]) & "','" & HOUR(Tabulka4[[#This Row],[N]]) & ":" & MINUTE(Tabulka4[[#This Row],[N]]) & "');" -> insert into trasy (zastavka,auto,R,O,N) values ('26','01','4:13','12:13','20:13');
B27: 59 | C27: 01 | D27: 0.18055556 | E27: 0.51388889 | F27: 0.84722222 | I27: ="insert into trasy (zastavka,auto,R,O,N) values ('" & Tabulka4[[#This Row],[zastavka]] & "','" & Tabulka4[[#This Row],[trasa]] & "','" & HOUR(Tabulka4[[#This Row],[R]]) & ":" & MINUTE(Tabulka4[[#This Row],[R]]) & "','" & HOUR(Tabulka4[[#This Row],[O]]) & ":" & MINUTE(Tabulka4[[#This Row],[O]]) & "','" & HOUR(Tabulka4[[#This Row],[N]]) & ":" & MINUTE(Tabulka4[[#This Row],[N]]) & "');" -> insert into trasy (zastavka,auto,R,O,N) values ('59','01','4:20','12:20','20:20');
... B130: 108 | C130: 16 | D130: 0.21180556 | E130: 0.54513889 | F130: 0.87847222 | I130: ="insert into trasy (zastavka,auto,R,O,N) values ('" & Tabulka4[[#This Row],[zastavka]] & "','" & Tabulka4[[#This Row],[trasa]] & "','" & HOUR(Tabulka4[[#This Row],[R]]) & ":" & MINUTE(Tabulka4[[#This Row],[R]]) & "','" & HOUR(Tabulka4[[#This Row],[O]]) & ":" & MINUTE(Tabulka4[[#This Row],[O]]) & "','" & HOUR(Tabulka4[[#This Row],[N]]) & ":" & MINUTE(Tabulka4[[#This Row],[N]]) & "');" -> insert into trasy (zastavka,auto,R,O,N) values ('108','16','5:5','13:5','21:5');

Sheet TRASY
B2: ID#1 | C2: Trasa | D2: Zastávka | E2: Kontrola | F2: Zastávka | G2: Čas R | H2: Čas O | I2: Čas N | J2: Čas NN | K2: Čas NR | L2: Čas VK | M2: Čas PR | N2: Editace | O2: Smaž
A3: =B3&E3 -> 0162 | B3: 01 | C3: ALLIANCE LAUNDRY 3 | D3: Radlin, Korfantego (Centrum) | E3: =VLOOKUP(D3,zastavky!C:D,2,0) -> 62 | F3: Radlin Centrum | G3: 0.17708333 | H3: 0 | I3: 0 | J3: 0 | K3: 0 | L3: 0 | M3: 0
A4: =B4&E4 -> 0182 | B4: 01 | C4: ALLIANCE LAUNDRY 3 | D4: Wodzisław Śląski, PKS / PKP | E4: =VLOOKUP(D4,zastavky!C:D,2,0) -> 82 | F4: Wodzislaw PKP, trasa 3 | G4: 0.19444444 | H4: 0 | I4: 0 | J4: 0 | K4: 0 | L4: 0 | M4: 0
A5: =B5&E5 -> 0148 | B5: 01 | C5: ALLIANCE LAUNDRY 3 | D5: Jastrzębie-Zdrój, ul. Wodzisławska (Hotel Czarny Rycerz) | E5: =VLOOKUP(D5,zastavky!C:D,2,0) -> 48 | F5: Jastrzębie Wodzisławska Czarny Rycerz | G5: 0.19791667 | H5: 0 | I5: 0 | J5: 0 | K5: 0 | L5: 0 | M5: 0
A6: =B6&E6 -> 02101 | B6: 02 | C6: ALLIANCE LAUNDRY 4 | D6: Żory, Bajerówka (ul. Jana Pawła II) | E6: =VLOOKUP(D6,zastavky!C:D,2,0) -> 101 | F6: Zory Bajerowka | G6: 0.16666667 | H6: 0 | I6: 0 | J6: 0 | K6: 0 | L6: 0 | M6: 0
A7: =B7&E7 -> 0236 | B7: 02 | C7: ALLIANCE LAUNDRY 4 | D7: Jastrzębie-Zdrój, Szeroka (Kaplica) | E7: =VLOOKUP(D7,zastavky!C:D,2,0) -> 36 | F7: Szeroka Kaplica | G7: 0.17361111 | H7: 0 | I7: 0 | J7: 0 | K7: 0 | L7: 0 | M7: 0
A8: =B8&E8 -> 0222 | B8: 02 | C8: ALLIANCE LAUNDRY 4 | D8: Jastrzębie-Zdrój, Al. Piłsudskiego (Pszczyńska/Rybnicka) | E8: =VLOOKUP(D8,zastavky!C:D,2,0) -> 22 | F8: Jastr.Zd. - Skrzyzovanie Pszczyńska/Rybnicka | G8: 0.17708333 | H8: 0 | I8: 0 | J8: 0 | K8: 0 | L8: 0 | M8: 0
A9: =B9&E9 -> 0225 | B9: 02 | C9: ALLIANCE LAUNDRY 4 | D9: Jastrzębie-Zdrój, Al. Piłsudskiego (Urząd Miasta) | E9: =VLOOKUP(D9,zastavky!C:D,2,0) -> 25 | F9: Jastrzebie Urzad Miasta Morcinka | G9: 0.17847222 | H9: 0 | I9: 0 | J9: 0 | K9: 0 | L9: 0 | M9: 0
A10: =B10&E10 -> 0218 | B10: 02 | C10: ALLIANCE LAUNDRY 4 | D10: Jastrzębie-Zdrój, Al. Piłsudskiego (McDonald's) | E10: =VLOOKUP(D10,zastavky!C:D,2,0) -> 18 | F10: Jastrzebie McDonalds | G10: 0.17986111 | H10: 0 | I10: 0 | J10: 0 | K10: 0 | L10: 0 | M10: 0
A11: =B11&E11 -> 0224 | B11: 02 | C11: ALLIANCE LAUNDRY 4 | D11: Jastrzębie-Zdrój, Al. Piłsudskiego (Supersam/Kaufland) | E11: =VLOOKUP(D11,zastavky!C:D,2,0) -> 24 | F11: Jastrzebie Supersam | G11: 0.18125 | H11: 0 | I11: 0 | J11: 0 | K11: 0 | L11: 0 | M11: 0
A12: =B12&E12 -> 0241 | B12: 02 | C12: ALLIANCE LAUNDRY 4 | D12: Jastrzębie-Zdrój, ul. 11 Listopada (Urząd Skarbowy) | E12: =VLOOKUP(D12,zastavky!C:D,2,0) -> 41 | F12: Jastrzebie Urzad Skarbowy | G12: 0.18402778 | H12: 0 | I12: 0 | J12: 0 | K12: 0 | L12: 0 | M12: 0
A13: =B13&E13 -> 0295 | B13: 02 | C13: ALLIANCE LAUNDRY 4 | D13: Zebrzydowice, Kino | E13: =VLOOKUP(D13,zastavky!C:D,2,0) -> 95 | F13: Zebrzydowice kino | G13: 0.19444444 | H13: 0 | I13: 0 | J13: 0 | K13: 0 | L13: 0 | M13: 0
A14: =B14&E14 -> 0213 | B14: 02 | C14: ALLIANCE LAUNDRY 4 | D14: Hażlach, Centrum (Skrzyżowanie obok stacji Crab) | E14: =VLOOKUP(D14,zastavky!C:D,2,0) -> 13 | F14: Halách Skrzyzowanie (Crab) | G14: 0.2 | H14: 0 | I14: 0 | J14: 0 | K14: 0 | L14: 0 | M14: 0
... A69: =B69&E69 -> 0695 | B69: 06 | C69: DSC 2 | D69: Zebrzydowice, Kino | E69: =VLOOKUP(D69,zastavky!C:D,2,0) -> 95 | F69: Zebrzydowice Rondo | G69: 0.20625 | H69: 0.53958333 | I69: 0.87291667 | J69: 1.20625 | K69: 1.5395833 | L69: 1.8729167 | M69: 2.20625
A70: =B70&E70 -> 0696 | B70: 06 | C70: DSC 2 | D70: Zebrzydowice, Ośrodek Zdrowia | E70: =VLOOKUP(D70,zastavky!C:D,2,0) -> 96 | F70: Zebrzydowice Ośrodek Zdrowia | G70: 0.20694444 | H70: 0.54027778 | I70: 0.87361111
A71: =B71&E71 -> 0652 | B71: 06 | C71: DSC 2 | D71: Kończyce Małe, Sklep | E71: =VLOOKUP(D71,zastavky!C:D,2,0) -> 52 | F71: Male Konczyce | G71: 0.20902778 | H71: 0.54236111 | I71: 0.87569444 | J71: 0.20833333 | K71: 0.20833333 | L71: 0.20833333 | M71: 0.20833333
A72: =B72&E72 -> 0603 | B72: 06 | C72: DSC 2 | D72: Cieszyn, ul. Katowicka (Cmentarz / Orlen / Biedronka) | E72: =VLOOKUP(D72,zastavky!C:D,2,0) -> 03 | F72: Cieszyn ul. Katowicka przystanek obok Biedronki | G72: 0.21527778 | H72: 0.54861111 | I72: 0.88194444 | J72: 0.20833333 | K72: 0.20833333 | L72: 0.20833333 | M72: 0.20833333
A73: =B73&E73 -> 0791 | B73: 07 | C73: GUZU 1 | D73: Wodzisław Śląski, Wilchwy (Blazy) | E73: =VLOOKUP(D73,zastavky!C:D,2,0) -> 91 | F73: Zory Sad | G73: 0.18055556 | H73: 0.68055556 | I73: 0 | J73: 0 | K73: 0 | L73: 0 | M73: 0
A74: =B74&E74 -> 0862 | B74: 08 | C74: HILITE 1 | D74: Radlin, Korfantego (Centrum) | E74: =VLOOKUP(D74,zastavky!C:D,2,0) -> 62 | F74: Radlin - Korfantego | G74: 0.19097222 | H74: 0.52430556 | I74: 0.85069444 | J74: 0.20833333 | K74: 0.20833333 | L74: 0.20833333 | M74: 0.20833333
A75: =B75&E75 -> 0890 | B75: 08 | C75: HILITE 1 | D75: Wodzisław Śląski, ul. Radlińska (Piekarnia Kłos) | E75: =VLOOKUP(D75,zastavky!C:D,2,0) -> 90 | F75: Wodzisław Śląski - Piekarnia Klos (ul. Radlinska - przystanek Os XXX - lecia) | G75: 0.20138889 | H75: 0.53472222 | I75: 0.86805556 | J75: 0.20833333 | K75: 0.20833333 | L75: 0.20833333 | M75: 0.20833333
A76: =B76&E76 -> 0882 | B76: 08 | C76: HILITE 1 | D76: Wodzisław Śląski, PKS / PKP | E76: =VLOOKUP(D76,zastavky!C:D,2,0) -> 82 | F76: Wodzisław Śląski - przystanek autobusowy PKP | G76: 0.20486111 | H76: 0.53819444 | I76: 0.87152778 | J76: 0.20833333 | K76: 0.20833333 | L76: 0.20833333 | M76: 0.20833333
A77: =B77&E77 -> 09107 | B77: 09 | C77: HILITE 2 | D77: Żory, ul. Wodzisławska (Milla) | E77: =VLOOKUP(D77,zastavky!C:D,2,0) -> 107 | F77: Źory Wodzislawska Mila (ul. Wodzislawska - przystanek kierunek swierklany) | G77: 0.18402778 | H77: 0.51736111 | I77: 0.85069444 | J77: 0.20833333 | K77: 0.20833333 | L77: 0.20833333 | M77: 0.20833333
A78: =B78&E78 -> 09100 | B78: 09 | C78: HILITE 2 | D78: Żory, Al. Zjednoczonej Europy (McDonald's) | E78: =VLOOKUP(D78,zastavky!C:D,2,0) -> 100 | F78: Źory McDonald (al. zjednocz. Europy - Archiwum) | G78: 0.1875 | H78: 0.52083333 | I78: 0.85416667 | J78: 0.20833333 | K78: 0.20833333 | L78: 0.20833333 | M78: 0.20833333
A79: =B79&E79 -> 09101 | B79: 09 | C79: HILITE 2 | D79: Żory, Bajerówka (ul. Jana Pawła II) | E79: =VLOOKUP(D79,zastavky!C:D,2,0) -> 101 | F79: Źory Bajerówka (al. Jana Pawla - przystanek) | G79: 0.18958333 | H79: 0.52291667 | I79: 0.85625 | J79: 0.20833333 | K79: 0.20833333 | L79: 0.20833333 | M79: 0.20833333
A80: =B80&E80 -> 0939 | B80: 09 | C80: HILITE 2 | D80: Jastrzębie-Zdrój, Szeroka (ul. Powstańców Śląskich/Biedronka) | E80: =VLOOKUP(D80,zastavky!C:D,2,0) -> 39 | F80: Jastrzebie Zdrój - Szeroka Biedronka (ul. Powstancow slaskich - parking naprzeciwko Biedronki) | G80: 0.19444444 | H80: 0.52777778 | I80: 0.86111111 | J80: 0.20833333 | K80: 0.20833333 | L80: 0.20833333 | M80: 0.20833333
A81: =B81&E81 -> 0917 | B81: 09 | C81: HILITE 2 | D81: Jastrzębie-Zdrój, Al. Piłsudskiego (Dubielec) | E81: =VLOOKUP(D81,zastavky!C:D,2,0) -> 17 | F81: Jastrzebie Zdrój - Dubielec (ul. Rybnicka - przystanek) | G81: 0.19791667 | H81: 0.53125 | I81: 0.86458333 | J81: 0.20833333 | K81: 0.20833333 | L81: 0.20833333 | M81: 0.20833333
A82: =B82&E82 -> 0933 | B82: 09 | C82: HILITE 2 | D82: Jastrzębie-Zdrój, Ranoszka | E82: =VLOOKUP(D82,zastavky!C:D,2,0) -> 33 | F82: Jastrzebie Zdrój - Ranoszka | G82: 0.2 | H82: 0.53333333 | I82: 0.86666667 | J82: 0.20833333 | K82: 0.20833333 | L82: 0.20833333 | M82: 0.20833333
... A97: =B97&E97 -> 1035 | B97: 10 | C97: TATRA - ALS - SPRINT | D97: Jastrzębie-Zdrój, Ruptawa (Ośrodek Zdrowia) | E97: =VLOOKUP(D97,zastavky!C:D,2,0) -> 35 | F97: Jastrzębie Zdroj - Ruptawa osrodek | G97: 0.18055556 | H97: 0.51388889 | I97: 0.84722222 | J97: 0.20833333 | K97: 0.20833333 | L97: 0.20833333 | M97: 0.20833333
A98: =B98&E98 -> 1034 | B98: 10 | C98: TATRA - ALS - SPRINT | D98: Jastrzębie-Zdrój, Ruptawa (Cisówka) | E98: =VLOOKUP(D98,zastavky!C:D,2,0) -> 34 | G98: 0.18402778 | H98: 0.51736111 | I98: 0.85069444
A99: =B99&E99 -> 1057 | B99: 10 | C99: TATRA - ALS - SPRINT | D99: Kończyce Wielkie, Spółdzielnia | E99: =VLOOKUP(D99,zastavky!C:D,2,0) -> 57 | F99: Końzyce Spóldzielnia | G99: 0.18472222 | H99: 0.51805556 | I99: 0.85138889 | J99: 0.20833333 | K99: 0.20833333 | L99: 0.20833333 | M99: 0.20833333
A100: =B100&E100 -> 1098 | B100: 10 | C100: TATRA - ALS - SPRINT | D100: Zebrzydowice, Rondo | E100: =VLOOKUP(D100,zastavky!C:D,2,0) -> 98 | F100: Zebrzydowice Rondo | G100: 0.18611111 | H100: 0.51944444 | I100: 0.85277778 | J100: 0.20833333 | K100: 0.20833333 | L100: 0.20833333 | M100: 0.20833333
A101: =B101&E101 -> 1013 | B101: 10 | C101: TATRA - ALS - SPRINT | D101: Hażlach, Centrum (Skrzyżowanie obok stacji Crab) | E101: =VLOOKUP(D101,zastavky!C:D,2,0) -> 13 | F101: Haźlach Crab | G101: 0.19444444 | H101: 0.52777778 | I101: 0.86111111 | J101: 0.20833333 | K101: 0.20833333 | L101: 0.20833333 | M101: 0.20833333
A102: =B102&E102 -> 1003 | B102: 10 | C102: TATRA - ALS - SPRINT | D102: Cieszyn, ul. Katowicka (Cmentarz / Orlen / Biedronka) | E102: =VLOOKUP(D102,zastavky!C:D,2,0) -> 03 | F102: Cieszyn Orlen | G102: 0.19791667 | H102: 0.53125 | I102: 0.86458333 | J102: 0.20833333 | K102: 0.20833333 | L102: 0.20833333 | M102: 0.20833333
A103: =B103&E103 -> 1004 | B103: 10 | C103: TATRA - ALS - SPRINT | D103: Cieszyn, ul. Liburnia (Kaufland) | E103: =VLOOKUP(D103,zastavky!C:D,2,0) -> 04 | F103: Cieszyn - Liburnia Kaufland | G103: 0.19930556 | H103: 0.53263889 | I103: 0.86597222 | J103: 0.20833333 | K103: 0.20833333 | L103: 0.20833333 | M103: 0.20833333
A104: =B104&E104 -> 1005 | B104: 10 | C104: TATRA - ALS - SPRINT | D104: Cieszyn, ul. Liburnia (Kościół) | E104: =VLOOKUP(D104,zastavky!C:D,2,0) -> 05 | F104: Cieszyn - Liburnia Kościól | G104: 0.20138889 | H104: 0.53472222 | I104: 0.86805556 | J104: 0.20833333 | K104: 0.20833333 | L104: 0.20833333 | M104: 0.20833333
A105: =B105&E105 -> 11104 | B105: 11 | C105: TATRA METALURGIE | D105: Żory, ul. Dąbrowskiego (Sąd) | E105: =VLOOKUP(D105,zastavky!C:D,2,0) -> 104 | F105: Żory Sąd | G105: 0.15763889 | H105: 0.49097222 | I105: 0.82430556 | J105: 0.20833333 | K105: 0.20833333 | L105: 0.20833333 | M105: 0.20833333
A106: =B106&E106 -> 11101 | B106: 11 | C106: TATRA METALURGIE | D106: Żory, Bajerówka (ul. Jana Pawła II) | E106: =VLOOKUP(D106,zastavky!C:D,2,0) -> 101 | F106: Žory - Bajerowka | G106: 0.15972222 | H106: 0.49305556 | I106: 0.82638889 | J106: 0.20833333 | K106: 0.20833333 | L106: 0.20833333 | M106: 0.20833333
A107: =B107&E107 -> 1178 | B107: 11 | C107: TATRA METALURGIE | D107: Rybnik, Śródmieście (Dworek) | E107: =VLOOKUP(D107,zastavky!C:D,2,0) -> 78 | F107: rybnik dworek parking trafo | G107: 0.16319444 | H107: 0.49652778 | I107: 0.82986111 | J107: 0.20833333 | K107: 0.20833333 | L107: 0.20833333 | M107: 0.20833333
A108: =B108&E108 -> 1177 | B108: 11 | C108: TATRA METALURGIE | D108: Rybnik, Smolna (obok Biedronki) | E108: =VLOOKUP(D108,zastavky!C:D,2,0) -> 77 | F108: rybnik smolna biedronka | G108: 0.16527778 | H108: 0.49861111 | I108: 0.83194444 | J108: 0.20833333 | K108: 0.20833333 | L108: 0.20833333 | M108: 0.20833333
A109: =B109&E109 -> 1136 | B109: 11 | C109: TATRA METALURGIE | D109: Jastrzębie-Zdrój, Szeroka (Kaplica) | E109: =VLOOKUP(D109,zastavky!C:D,2,0) -> 36 | F109: Szeroka - Kaplica | G109: 0.16527778 | H109: 0.49861111 | I109: 0.83194444 | J109: 0.20833333 | K109: 0.20833333 | L109: 0.20833333 | M109: 0.20833333
...

Sheet PIVOT
A1: Trasa | B1: Zastávka | C1: Čas R | D1: Čas O | E1: Čas N
A2: ALLIANCE LAUNDRY 3 | B2: Radlin, Korfantego (Centrum) | C2: 0.17708333 | D2: 0 | E2: 0
B3: Wodzisław Śląski, PKS / PKP | C3: 0.19444444 | D3: 0 | E3: 0
B4: Jastrzębie-Zdrój, ul. Wodzisławska (Hotel Czarny Rycerz) | C4: 0.19791667 | D4: 0 | E4: 0
A5: ALLIANCE LAUNDRY 3 Celkem
A6: ALLIANCE LAUNDRY 4 | B6: Żory, Bajerówka (ul. Jana Pawła II) | C6: 0.16666667 | D6: 0 | E6: 0
B7: Jastrzębie-Zdrój, Szeroka (Kaplica) | C7: 0.17361111 | D7: 0 | E7: 0
B8: Hażlach, Centrum (Skrzyżowanie obok stacji Crab) | C8: 0.2 | D8: 0 | E8: 0
B9: Jastrzębie-Zdrój, Al. Piłsudskiego (Pszczyńska/Rybnicka) | C9: 0.17708333 | D9: 0 | E9: 0
B10: Jastrzębie-Zdrój, Al. Piłsudskiego (Urząd Miasta) | C10: 0.17847222 | D10: 0 | E10: 0
B11: Jastrzębie-Zdrój, Al. Piłsudskiego (McDonald's) | C11: 0.17986111 | D11: 0 | E11: 0
B12: Jastrzębie-Zdrój, Al. Piłsudskiego (Supersam/Kaufland) | C12: 0.18125 | D12: 0 | E12: 0
B13: Jastrzębie-Zdrój, ul. 11 Listopada (Urząd Skarbowy) | C13: 0.18402778 | D13: 0 | E13: 0
B14: Zebrzydowice, Kino | C14: 0.19444444 | D14: 0 | E14: 0
B15: Cieszyn, ul. Katowicka (Cmentarz / Orlen / Biedronka) | C15: 0.20486111 | D15: 0 | E15: 0
B16: Cieszyn, ul. Liburnia (Starostwo Powiatowe) | C16: 0.20625 | D16: 0 | E16: 0
B17: Cieszyn, ul. Liburnia (Kościół) | C17: 0.20833333 | D17: 0 | E17: 0
A18: ALLIANCE LAUNDRY 4 Celkem
A19: BATZ 1 | B19: Jastrzębie-Zdrój, Al. Piłsudskiego (Dubielec) | C19: 0.1625 | D19: 0.49583333 | E19: 0.82916667
B20: Jastrzębie-Zdrój, Szeroka (ul. Rybnicka) | C20: 0.15972222 | D20: 0.49305556 | E20: 0.82638889
B21: Jastrzębie-Zdrój, Szeroka (ul. Powstańców Śląskich/Biedronka) | C21: 0.16111111 | D21: 0.49444444 | E21: 0.82777778
B22: Jastrzębie-Zdrój, Al. Piłsudskiego (Pszczyńska/Rybnicka) | C22: 0.16527778 | D22: 0.49861111 | E22: 0.83194444
B23: Jastrzębie-Zdrój, Al. Piłsudskiego (Urząd Miasta) | C23: 0.16805556 | D23: 0.50138889 | E23: 0.83472222
B24: Jastrzębie-Zdrój, Al. Piłsudskiego (Supersam/Kaufland) | C24: 0.16944444 | D24: 0.50277778 | E24: 0.83611111
B25: Jastrzębie-Zdrój, Al. Jana Pawła II (Hala Sportowa) | C25: 0.17222222 | D25: 0.50555556 | E25: 0.83888889
B26: Jastrzębie-Zdrój, Dworzec Autobusowy (ul. Sybiraków - Mała Strona) | C26: 0.17361111 | D26: 0.50694444 | E26: 0.84027778 | F26: není
B27: Jastrzębie-Zdrój, Armii Krajowej | C27: 0.17569444 | D27: 0.50902778 | E27: 0.84236111
B28: Mszana, Centrum / Urząd Gminy | C28: 0.18055556 | D28: 0.51388889 | E28: 0.84722222
B29: Wodzisław Śląski, Stacja Paliw Circle K / McDonald's | C29: 0.1875 | D29: 0.52083333 | E29: 0.85416667
B30: Wodzisław Śląski, Dworzec Autobusowy (Galeria Karuzela) | C30: 0.18958333 | D30: 0.52291667 | E30: 0.85625
B31: Wodzisław Śląski, ul. Bogumińska (Cmentarz/Działki) | C31: 0.19166667 | D31: 0.525 | E31: 0.85833333
B32: Gorzyce, Urząd Gminy | C32: 0.19791667 | D32: 0.53125 | E32: 0.86458333
B33: Gorzyczki, UNIWAR | C33: 0.20138889 | D33: 0.53472222 | E33: 0.86805556
B34: Ostrava (CZ), Dřevoprodej | C34: 0.21527778 | D34: 0.54861111 | E34: 0.88194444
B35: Frýdek-Místek (CZ), Stacja Benzina / KMJ | C35: 0.22222222 | D35: 0.55555556 | E35: 0.88888889
A36: BATZ 1 Celkem
A37: BATZ 2 | B37: Żory, ul. Dworcowa (Parking Netto) | C37: 0.17361111 | D37: 0.50694444 | E37: 0.84027778
B38: Żory, Sąd Rejonowy (Al. Jana Pawła II) | C38: 0.17708333 | D38: 0.51041667 | E38: 0.84375
B39: Żory, Bajerówka (ul. Jana Pawła II) | C39: 0.17847222 | D39: 0.51180556 | E39: 0.84513889
B40: Jastrzębie-Zdrój, Ruptawa (Cisówka) | C40: 0.19444444 | D40: 0.52777778 | E40: 0.86111111
...
