Workbook
Name A: DATA!$AZ$2:$AZ$9
Name Firma: DATA!$R$3:$R$10
Name Průřez_Absence: #N/A
Name Průřez_Doprava: #N/A
Name Průřez_Přítomnost___Směna: #N/A
Name Směny: DATA!$AY$2:$AY$6
Name Úvazek: DATA!$AX$2:$AX$3

Sheet DATA
A1: IND# | B1: ID | C1: Příjmení | D1: Jméno | E1: Os.č. | F1: Os.č.kl. | G1: RFID | H1: Telefon | I1: Vstup | J1: Výstup | K1: Doprava | L1: Nástup | M1: Směna | N1: Cílová st. | O1: Docházka | P1: Editace | R1: Firma | S1: IND# | T1: IND# | U1: IND# | V1: IND# | W1: IND# | X1: IND# | Y1: IND# | Z1: IND# | AX1: Úvazek | AY1: Směny | AZ1: A
A2: =C2&" "&D2 -> Adamczewski Amadeusz | B2: 1 | C2: Adamczewski | D2: Amadeusz | E2: 6275 | F2: 0 | G2: 13210313 | H2: 48570666458 | I2: 45748 | J2: 73050 | K2: Vlastní auto | L2: Vlastní auto | M2: R / N/A | N2: Hilite | O2: 0.20836806 | S2: Baka Przemyslaw | T2: Bilicer Natalia | U2: Bojda Lukasz | V2: Adamiak Magdalena | W2: Rojek Daniel | X2: Adamczewski Amadeusz | Y2: Bieniek Krystian | Z2: Belica Bartosz | AX2: 0.3125 | AY2: R | AZ2: Dovolená
A3: =C3&" "&D3 -> Adamiak Magdalena | B3: 2 | C3: Adamiak | D3: Magdalena | E3: 5777 | F3: 0 | G3: 315321941 | H3: 48799785300 | I3: 45502 | J3: 73050 | K3: BATZ 2 | L3: Źory - Sąd Rejonowy | M3: R / N/A | N3: BATZ | O3: 0.16961806 | R3: ALLIANCE | S3: Banot Katarzyna | T3: Brachman Piotr Leszek | U3: Brodowski Robert | V3: Bartoň Edyta | W3: Szweda Krzysztof | X3: Balwierz Piotr Marian | Y3: Ceglarski Wojciech | Z3: Gordienko Adam | AX3: 0.5 | AY3: O | AZ3: Nemoc
A4: =C4&" "&D4 -> Baka Przemyslaw | B4: 3 | C4: Baka | D4: Przemyslaw | E4: 6537 | F4: 0 | G4: 11066856 | H4: 48572475445 | I4: 45901 | J4: 73050 | K4: DSC 2 | L4: Jastrzębie-Zdrój HALA przyst. autobus. Hala Sportowa | M4: O / N/A | N4: DSC | R4: BATZ | S4: Bassler Lukáš | T4: Bujak Beniamin Salamon | U4: Doliński Roman | V4: Belej Karina | W4: Zlotkowski Miroslaw | X4: Boruszka Aneta Barbara | Y4: Ganczorz Tomasz | Z4: Gorka Dawid | AY4: N | AZ4: Lékař
A5: =C5&" "&D5 -> Balwierz Piotr Marian | B5: 4 | C5: Balwierz | D5: Piotr Marian | E5: 4673 | F5: 70187 | G5: 11978487 | H5: 48785949300 | I5: 44805 | J5: 73050 | K5: HILITE 2 | L5: Jastrzebie Zdrój McDonald (al. J. Pilsudskiego - przystanek) | M5: R / N/A | N5: HILITE | R5: DONGHEE | S5: Baszczynski Bogdan | T5: Ciesielska Malgorzata | U5: Grabka Daniel | V5: Bortlik Dawid | X5: Gozdur Oliwia Katarzyna | Y5: Goik Andrzej | Z5: Siekierski Filip | AY5: - | AZ5: Prostoj
A6: =C6&" "&D6 -> Banot Katarzyna | B6: 5 | C6: Banot | D6: Katarzyna | E6: 5802 | F6: R1225-01 | G6: 7421727 | H6: 48786907150 | I6: 45516 | J6: 73050 | K6: Vlastní auto | L6: Vlastní auto | M6: R / N/A | N6: DSC | O6: 0.20836806 | R6: DSC | S6: Bialas Elzbieta | T6: Dalemula Radoslaw Jakub | U6: Jablonski Slawomir | V6: Bujok Dominik | X6: Herok-Legec Jolanta | Y6: Chojnacki Piotr | AY6: A | AZ6: Narozeninový den
A7: =C7&" "&D7 -> Bartoň Edyta | B7: 6 | C7: Bartoň | D7: Edyta | E7: 4838 | F7: 4838 | G7: 328608648 | H7: 48793386811 | I7: 44944 | J7: 73050 | K7: BATZ 2 | L7: Ruptawa - Cisówka | M7: R / N/A | N7: BATZ | R7: GUZU | S7: Bialozyt Joanna | T7: Duraj Mateusz Jan | U7: Koblanski Daniel | V7: Bury Angelika | X7: Hodulík Mikuláš | Y7: Janiczek Kamil Patryk | AZ7: Omluvená-Paragraf
A8: =C8&" "&D8 -> Bassler Lukáš | B8: 7 | C8: Bassler | D8: Lukáš | E8: 4869 | F8: R0878-01 | G8: 1833613 | H8: 722775976 | I8: 45013 | J8: 73050 | K8: Vlastní auto | L8: Vlastní auto | M8: N / N/A | N8: DSC | O8: 0.87502315 | R8: HILITE | S8: Bochenek Adam Piotr | T8: Giedziun Monika | U8: Madrzyk Ryszard | V8: Buturla Bozena | X8: Hodulík Mikuláš | Y8: Jarosz Mariusz | AZ8: Neplacené volno
A9: =C9&" "&D9 -> Baszczynski Bogdan | B9: 8 | C9: Baszczynski | D9: Bogdan | E9: 6508 | F9: 0 | G9: 0 | H9: 48792742229 | I9: 45887 | J9: 73050 | K9: Vlastní auto | L9: Vlastní auto | M9: O / N/A | N9: DSC | R9: TATRA | S9: Bochenek Damian Krzysztof | T9: Grzywacz Klaudia | U9: Mrozek Mateusz | V9: Buza Grazyna Aniela | X9: Huptys Wieslawa | Y9: Jaworski Dariusz | AZ9: Neomluvená
A10: =C10&" "&D10 -> Belej Karina | B10: 9 | C10: Belej | D10: Karina | E10: 4599 | F10: 4599 | G10: 348342254 | H10: 48723005113 | I10: 44757 | J10: 73050 | K10: BATZ 1 | L10: Jastrzebie Zdroj Dworzec autobusowy | M10: N / N/A | N10: BATZ | O10: 0.84144676 | R10: THERMA | S10: Borska Ewa | T10: Grzywacz Zbigniew | U10: Podżorski Andrzej | V10: Buza Jan Ireneusz | X10: Kaczmarczyk Jagna | Y10: Klonowski Piotr
A11: =C11&" "&D11 -> Belica Bartosz | B11: 10 | C11: Belica | D11: Bartosz | E11: 6474 | F11: 0 | G11: 1430027 | H11: 48721505226 | I11: 45860 | J11: 73050 | K11: BATZ 1 | L11: Jastr.Zd. - Aleje Piłsudskiego SUPERSAM | M11: O / N/A | N11: THERMA | S11: Bujak Leszek Sylwester | T11: Hak Joanna | U11: Salata Krzysztof Marek | V11: Cwiklak Robert | X11: Kolanowski Dawid Piotr | Y11: Kordowski Henryk
A12: =C12&" "&D12 -> Bialas Elzbieta | B12: 11 | C12: Bialas | D12: Elzbieta | E12: 4607 | F12: R0707-01 | G12: 4942265 | H12: 48881267099 | I12: 44781 | J12: 73050 | K12: DSC 2 | L12: Źory Bajerówka przyst. autobus. Al. Jana Pawła II Bajerówka | M12: R / N/A | N12: DSC | O12: 0.17989583 | S12: Cwiklinska Alicja Katarzyna | T12: Halama Pawel | U12: Slusarczyk Slawomir | V12: Dalemula Krysztof Grzegorz | X12: Korcz Wioleta | Y12: Kovařčik Tomáš
A13: =C13&" "&D13 -> Bialozyt Joanna | B13: 12 | C13: Bialozyt | D13: Joanna | E13: 5047 | F13: R0993-01 | G13: 1988772 | H13: 48510238811 | I13: 45159 | J13: 73050 | K13: Vlastní auto | L13: Vlastní auto | M13: N / N/A | N13: DSC | O13: 0.87502315 | S13: Czajka Bartosz | T13: Hernik Krzysztof | U13: Smagon Damian | V13: Derlacz Piotr | X13: Lebok Karolina | Y13: Koza Adam
A14: =C14&" "&D14 -> Bieniek Krystian | B14: 13 | C14: Bieniek | D14: Krystian | E14: 6329 | F14: 0 | G14: 400218349 | H14: 48793183757 | I14: 45775 | J14: 73050 | K14: TATRA METALURGIE | L14: Rybnik Dworek | M14: R / N/A | N14: TATRA | O14: 0.17210648 | S14: Damis Malgorzata Maria | T14: Iwanek Rafal | U14: Sztymelski Lukasz | V14: Dolezych Lidia | X14: Nowak-Michalecka Katarzyna | Y14: Lichacz Piotr
A15: =C15&" "&D15 -> Bilicer Natalia | B15: 14 | C15: Bilicer | D15: Natalia | E15: 6259 | F15: 0 | G15: 1203746 | H15: 48536393632 | I15: 45743 | J15: 73050 | K15: Vlastní auto | L15: Vlastní auto | M15: R / N/A | N15: Donghee | O15: 0.20836806 | S15: Ferszt Tomasz | T15: Kowalewski Marcin | U15: Szurman Krystian | V15: Fitrzyková Jana | X15: Peterková Dagmar | Y15: Marczewski Robert Wieslaw
A16: =C16&" "&D16 -> Bochenek Adam Piotr | B16: 15 | C16: Bochenek | D16: Adam Piotr | E16: 4961 | F16: R0936-01 | G16: 1928484 | H16: 48790550612 | I16: 45057 | J16: 73050 | K16: Vlastní auto | L16: Vlastní auto | M16: O / N/A | N16: DSC | S16: Feszter Ewa | T16: Kuklinska Marlena | U16: Tabor Konrad | V16: Gorka Grzegorz | X16: Szewczyk Agnieszka | Y16: Nawara Bartosz Pawel
A17: =C17&" "&D17 -> Bochenek Damian Krzysztof | B17: 16 | C17: Bochenek | D17: Damian Krzysztof | E17: 4616 | F17: R0709-01 | G17: 1405843 | H17: 48600636889 | I17: 44781 | J17: 73050 | K17: Vlastní auto | L17: Vlastní auto | M17: R / N/A | N17: DSC | O17: 0.20835648 | S17: Fojcik Marzena | T17: Lebiediew Sławomir | U17: Tomica Artur | V17: Chodinský Rostislav | X17: Wardzala Nicolla | Y17: Onderka Jan
A18: =C18&" "&D18 -> Bojda Lukasz | B18: 17 | C18: Bojda | D18: Lukasz | E18: 6197 | F18: 0 | G18: 1197174 | H18: 48516752290 | I18: 45712 | J18: 73050 | K18: ALLIANCE LAUNDRY 4 | L18: Cieszyn Liburnia Starostwo | M18: R / N/A | N18: ALLIANCE LAUNDRY | O18: 0.20515046 | S18: Gawel Krystian | T18: Lorenc Pawel Jan | U18: Tworzydło Slawomir | V18: Janik-Rurarz Izabela | X18: Wasik Izabela | Y18: Pawlowski Kamil
A19: =C19&" "&D19 -> Borska Ewa | B19: 18 | C19: Borska | D19: Ewa | E19: 4721 | F19: R0768-01 | G19: 3370037 | H19: 48882717094 | I19: 44837 | J19: 73050 | K19: DSC 2 | L19: Źory Sąd przyst. autobus. Al. Jana Pawła II Sąd | M19: O / N/A | N19: DSC | S19: Golyszna Daria Anna | T19: Małczak Krzysztof | U19: Żwirek Arkadiusz | V19: Juszczak Jadwiga | X19: Zarebska Ewa | Y19: Pitel Jiří
A20: =C20&" "&D20 -> Bortlik Dawid | B20: 19 | C20: Bortlik | D20: Dawid | E20: 6566 | F20: 0 | G20: 391236060 | H20: 48503703769 | I20: 45915 | J20: 73050 | K20: BATZ 1 | L20: Jastr.Zd. - Aleje Piłsudskiego SUPERSAM | M20: R / N/A | N20: BATZ | O20: 0.17748843 | S20: Gora Renata | T20: Małka Artur | U20: Żwirek Dawid | V20: Konieczny Joanna | X20: Zeromska Aleksandra | Y20: Prudel Mateusz Stanislaw
A21: =C21&" "&D21 -> Boruszka Aneta Barbara | B21: 20 | C21: Boruszka | D21: Aneta Barbara | E21: 3415 | F21: R82 | G21: 12989719 | H21: 48605522989 | I21: 44228 | J21: 73050 | K21: HILITE 2 | L21: Jastrzebie Zdrój - Szeroka Biedronka (ul. Powstancow slaskich - parking naprzeciwko Biedronki) | M21: R / N/A | N21: HILITE | S21: Groborz Paulina Dominika | T21: Mielczarek Patrycjusz | V21: Kotowski Zbigniew Marek | X21: Blonski Marcin Ireneusz | Y21: Siedlok Zbigniew
A22: =C22&" "&D22 -> Brachman Piotr Leszek | B22: 21 | C22: Brachman | D22: Piotr Leszek | E22: 3951 | F22: 7547 | G22: 13392876 | H22: 48516350901 | I22: 44825 | J22: 73050 | K22: Vlastní auto | L22: Vlastní auto | M22: O / N/A | N22: DONGHEE | S22: Gromek Sylwia | T22: Milek Michal Jerzy | V22: Kozielski Kozielski Andrzej Jozef | X22: Jerchewicz Iwona | Y22: Stohandel Artur
A23: =C23&" "&D23 -> Brodowski Robert | B23: 22 | C23: Brodowski | D23: Robert | E23: 5683 | F23: 0 | G23: 11713635 | H23: 48508245715 | I23: 45461 | J23: 73050 | K23: ALLIANCE LAUNDRY 3 | L23: Radlin Centrum | M23: R / N/A | N23: ALLIANCE LAUNDRY | S23: Habierska Maja | T23: Mochnacz Lukasz Teodor | V23: Krensel Maria | Y23: Święty Czesław
A24: =C24&" "&D24 -> Bujak Leszek Sylwester | B24: 23 | C24: Bujak | D24: Leszek Sylwester | E24: 4845 | F24: R0862-01 | G24: 291517620 | H24: 48799082871 | I24: 44986 | J24: 73050 | K24: Vlastní auto | L24: Vlastní auto | M24: O / N/A | N24: DSC | S24: Herok Natalia Magdalena | T24: Niewiadomski Michal | V24: Krótki Gabriel | Y24: Sypulek Dariusz
A25: =C25&" "&D25 -> Bujak Beniamin Salamon | B25: 24 | C25: Bujak | D25: Beniamin Salamon | E25: 4894 | F25: 7503 | G25: 11966825 | H25: 48889843724 | I25: 44986 | J25: 73050 | K25: Vlastní auto | L25: Vlastní auto | M25: O / N/A | N25: DONGHEE | S25: Holeksa Mariola | T25: Nowakowska Magdalena | V25: Kuklińska Malgorzata | Y25: Szalamacha Maciej
A26: =C26&" "&D26 -> Bujok Dominik | B26: 25 | C26: Bujok | D26: Dominik | E26: 5094 | F26: 5094 | G26: 11754146 | H26: 48795139997 | I26: 45096 | J26: 73050 | K26: BATZ 2 | L26: Cieszyn Liburnia | M26: O / N/A | N26: BATZ | S26: Chalimoniuk Igor | T26: Palička Jiří | V26: Marczak Joanna | Y26: Szalamacha Wojciech
A27: =C27&" "&D27 -> Bury Angelika | B27: 26 | C27: Bury | D27: Angelika | E27: 6001 | F27: 0 | G27: 12020053 | H27: 48575311504 | I27: 45582 | J27: 73050 | K27: BATZ 1 | L27: Jastr.Zd. - Aleje Piłsudskiego SUPERSAM | M27: O / N/A | N27: BATZ | S27: Chciuk Lukasz | T27: Pawlak Marcin | V27: Marczak Maria Katarzyna | Y27: Szmyt Dariusz
A28: =C28&" "&D28 -> Buturla Bozena | B28: 27 | C28: Buturla | D28: Bozena | E28: 6573 | F28: 0 | G28: 391112974 | H28: 48669267044 | I28: 45922 | J28: 73050 | K28: BATZ 1 | L28: Wodzisław Śląski stacja paliw Circle K/McDonalds | M28: O / N/A | N28: BATZ | S28: Chlebek Aleksandra Ewa | T28: Poloczek Jadwiga Barbara | V28: Marekwica Adrian | Y28: Szopa Daniel
A29: =C29&" "&D29 -> Buza Grazyna Aniela | B29: 28 | C29: Buza | D29: Grazyna Aniela | E29: 5129 | F29: 5129 | G29: 328432941 | H29: 48788217740 | I29: 45145 | J29: 73050 | K29: BATZ 1 | L29: Szeroka ul. Rybnicka | M29: N / N/A | N29: BATZ | O29: 0.83196759 | S29: Chodorowska Barbara Miroslawa | T29: Poloczek Sebastian | V29: Matusiak Orfeusz Marek | Y29: Szrejder Sebastian
A30: =C30&" "&D30 -> Buza Jan Ireneusz | B30: 29 | C30: Buza | D30: Jan Ireneusz | E30: 5663 | F30: 4919 | G30: 328443812 | H30: 48531216624 | I30: 45012 | J30: 73050 | K30: BATZ 1 | L30: Szeroka ul. Rybnicka | M30: N / N/A | N30: BATZ | O30: 0.83158565 | S30: Jakubiec Krzysztof Grzegorz | T30: Rak Sławomir | V30: Meyer Beata | Y30: Trzmielowski Adrian Adam
A31: =C31&" "&D31 -> Ceglarski Wojciech | B31: 30 | C31: Ceglarski | D31: Wojciech | E31: 6212 | F31: 0 | G31: 0 | H31: 48788116032 | I31: 45721 | J31: 45933 | K31: TATRA METALURGIE | L31: Cieszyn Liburnia Starostwo | M31: N/A / R | N31: Tatra | S31: Jamry Kamil | T31: Regulski Adrian | V31: Michalec Regina | Y31: Waszut Lukasz
A32: =C32&" "&D32 -> Ciesielska Malgorzata | B32: 31 | C32: Ciesielska | D32: Malgorzata | E32: 6450 | F32: 0 | G32: 12099337 | H32: 48514893548 | I32: 45852 | J32: 73050 | K32: DSC 2 | L32: Źory Sąd przyst. autobus. Al. Jana Pawła II Sąd | M32: O / N/A | N32: Donghee | S32: Janczuk Mariola Anna | T32: Stanisz Pawel Piotr | V32: Mottlová Markéta | Y32: Wiącek Robert
A33: =C33&" "&D33 -> Cwiklak Robert | B33: 32 | C33: Cwiklak | D33: Robert | E33: 4936 | F33: 4936 | G33: 370049042 | H33: 48661575386 | I33: 45027 | J33: 73050 | K33: BATZ 1 | L33: Wodzisław Śląski stacja paliw Circle K/McDonalds | M33: O / N/A | N33: BATZ | S33: Kalisz Patrycja | T33: Wawrzyczek Arkadiusz | V33: Nowak Martyna | Y33: Wieszolek Adam
A34: =C34&" "&D34 -> Cwiklinska Alicja Katarzyna | B34: 33 | C34: Cwiklinska | D34: Alicja Katarzyna | E34: 47 | F34: R0340-01 | G34: 13123141 | H34: 48573239948 | I34: 44593 | J34: 73050 | K34: DSC 1 | L34: Radlin - Marcel przyst. autobus. Korfantego KWK | M34: N/A / N/A | N34: DSC | S34: Korab Karina Weronika | T34: Zajac Tomasz | V34: Opyd Marzena | Y34: Właśniak Dariusz
A35: =C35&" "&D35 -> Czajka Bartosz | B35: 34 | C35: Czajka | D35: Bartosz | E35: 6582 | F35: 0 | G35: 0 | H35: 48502143429 | I35: 45929 | J35: 73050 | K35: DSC 1 | L35: Wilchwy przystanek autobusowy Szkola | M35: R / N/A | N35: DSC | S35: Kotas Barbara Mariola | T35: Zymelka Krzysztof | V35: Ostafin Klaudia | Y35: Zybul Paweł
A36: =C36&" "&D36 -> Dalemula Krysztof Grzegorz | B36: 35 | C36: Dalemula | D36: Krysztof Grzegorz | E36: 4955 | F36: 4955 | G36: 370035234 | H36: 48691339886 | I36: 45033 | J36: 73050 | K36: BATZ 1 | L36: Wodzisław Śląski stacja paliw Circle K/McDonalds | M36: N / N/A | N36: BATZ | O36: 0.8546875 | S36: Kowaczik Bozena Jadwiga | T36: Hak Agnieszka | V36: Pajor Jolanta Wanda | Y36: Zynda Wieslaw Józef
A37: =C37&" "&D37 -> Dalemula Radoslaw Jakub | B37: 36 | C37: Dalemula | D37: Radoslaw Jakub | E37: 3359 | F37: 7685 | G37: 11727280 | H37: 48575017608 | I37: 44477 | J37: 73050 | K37: DSC 1 | L37: Rydultowy Dworzec Autobusowy | M37: N / N/A | N37: DONGHEE | O37: 0.83476852 | S37: Králová Eliška | T37: Chrzanowska Danuta | V37: Piechaczek Agnieszka | Y37: Kala Janusz Eryk
A38: =C38&" "&D38 -> Damis Malgorzata Maria | B38: 37 | C38: Damis | D38: Malgorzata Maria | E38: 49 | F38: R0088-02 | G38: 9531966 | H38: 48511553878 | I38: 44593 | J38: 73050 | K38: DSC 2 | L38: Zebrzydowice | M38: N / N/A | N38: DSC | S38: Kurasik Monika Dorota | T38: Jachym Sebastian | V38: Rak Barbara Irena | Y38: Możdżeń Dariusz
A39: =C39&" "&D39 -> Derlacz Piotr | B39: 38 | C39: Derlacz | D39: Piotr | E39: 6581 | F39: 0 | G39: 0 | H39: 48502167295 | I39: 45929 | J39: 73050 | K39: BATZ 1 | L39: Wodzisław Śląski Dworzec Autobus. Galeria Karuzela | M39: N / N/A | N39: BATZ | S39: Latka Ewelina Ewa | T39: Kowalski Damian | V39: Salamon Krzysztof | Y39: Skierka Dariusz
A40: =C40&" "&D40 -> Dolezych Lidia | B40: 39 | C40: Dolezych | D40: Lidia | E40: 6568 | F40: 0 | G40: 391211437 | H40: 48533341727 | I40: 45915 | J40: 73050 | K40: BATZ 2 | L40: Źory - Sąd Rejonowy | M40: R / N/A | N40: BATZ | O40: 0.16336806 | S40: Luczkowski Artur | T40: Murawski Kamil | V40: Sikora Teresa Michalina
...

Sheet 2025
B1: Datum | C1: Firma | D1: Pracovník | E1: Os. Číslo | F1: Přítomnost / Směna | G1: Absence | H1: Úvazek | I1: Doprava | J1: Přesčas | K1: Poznámka
A2: =IFERROR(IF(Tabulka2[[#This Row],[Datum]]=0,"!!! Vyplň DATUM !!!",IF(AND(Tabulka2[[#This Row],[Datum]]>0,Tabulka2[[#This Row],[Firma]]=0),"!!! Vyplň FIRMU !!!",IF(AND(Tabulka2[[#This Row],[Datum]]>0,Tabulka2[[#This Row],[Firma]]>0,Tabulka2[[#This Row],[Pracovník]]=0),"!!! Vyplň PRACOVNÍKA !!!",IF(AND(Tabulka2[[#This Row],[Datum]]>0,Tabulka2[[#This Row],[Firma]]>0,Tabulka2[[#This Row],[Pracovník]]>0,Tabulka2[[#This Row],[Přítomnost / Směna]]=0),"!!! Vyplň SMĚNU !!!","")))),"") | B2: 45924 | C2: BATZ | D2: Adamiak Magdalena | E2: =IFERROR(VLOOKUP(Tabulka2[[#This Row],[Pracovník]],DATA!A:L,5,0),"") -> 5777 | F2: O | I2: =IFERROR(VLOOKUP(Tabulka2[[#This Row],[Pracovník]],DATA!A:L,11,0),"") -> BATZ 2
A3: =IFERROR(IF(Tabulka2[[#This Row],[Datum]]=0,"!!! Vyplň DATUM !!!",IF(AND(Tabulka2[[#This Row],[Datum]]>0,Tabulka2[[#This Row],[Firma]]=0),"!!! Vyplň FIRMU !!!",IF(AND(Tabulka2[[#This Row],[Datum]]>0,Tabulka2[[#This Row],[Firma]]>0,Tabulka2[[#This Row],[Pracovník]]=0),"!!! Vyplň PRACOVNÍKA !!!",IF(AND(Tabulka2[[#This Row],[Datum]]>0,Tabulka2[[#This Row],[Firma]]>0,Tabulka2[[#This Row],[Pracovník]]>0,Tabulka2[[#This Row],[Přítomnost / Směna]]=0),"!!! Vyplň SMĚNU !!!","")))),"") | B3: 45924 | C3: BATZ | D3: Bartoň Edyta | E3: =IFERROR(VLOOKUP(Tabulka2[[#This Row],[Pracovník]],DATA!A:L,5,0),"") -> 4838 | F3: N | I3: =IFERROR(VLOOKUP(Tabulka2[[#This Row],[Pracovník]],DATA!A:L,11,0),"") -> BATZ 2
A4: =IFERROR(IF(Tabulka2[[#This Row],[Datum]]=0,"!!! Vyplň DATUM !!!",IF(AND(Tabulka2[[#This Row],[Datum]]>0,Tabulka2[[#This Row],[Firma]]=0),"!!! Vyplň FIRMU !!!",IF(AND(Tabulka2[[#This Row],[Datum]]>0,Tabulka2[[#This Row],[Firma]]>0,Tabulka2[[#This Row],[Pracovník]]=0),"!!! Vyplň PRACOVNÍKA !!!",IF(AND(Tabulka2[[#This Row],[Datum]]>0,Tabulka2[[#This Row],[Firma]]>0,Tabulka2[[#This Row],[Pracovník]]>0,Tabulka2[[#This Row],[Přítomnost / Směna]]=0),"!!! Vyplň SMĚNU !!!","")))),"") | B4: 45924 | C4: BATZ | D4: Belej Karina | E4: =IFERROR(VLOOKUP(Tabulka2[[#This Row],[Pracovník]],DATA!A:L,5,0),"") -> 4599 | F4: O | I4: =IFERROR(VLOOKUP(Tabulka2[[#This Row],[Pracovník]],DATA!A:L,11,0),"") -> BATZ 1
A5: =IFERROR(IF(Tabulka2[[#This Row],[Datum]]=0,"!!! Vyplň DATUM !!!",IF(AND(Tabulka2[[#This Row],[Datum]]>0,Tabulka2[[#This Row],[Firma]]=0),"!!! Vyplň FIRMU !!!",IF(AND(Tabulka2[[#This Row],[Datum]]>0,Tabulka2[[#This Row],[Firma]]>0,Tabulka2[[#This Row],[Pracovník]]=0),"!!! Vyplň PRACOVNÍKA !!!",IF(AND(Tabulka2[[#This Row],[Datum]]>0,Tabulka2[[#This Row],[Firma]]>0,Tabulka2[[#This Row],[Pracovník]]>0,Tabulka2[[#This Row],[Přítomnost / Směna]]=0),"!!! Vyplň SMĚNU !!!","")))),"") | B5: 45924 | C5: BATZ | D5: Bortlik Dawid | E5: =IFERROR(VLOOKUP(Tabulka2[[#This Row],[Pracovník]],DATA!A:L,5,0),"") -> 6566 | F5: N | I5: =IFERROR(VLOOKUP(Tabulka2[[#This Row],[Pracovník]],DATA!A:L,11,0),"") -> BATZ 1
A6: =IFERROR(IF(Tabulka2[[#This Row],[Datum]]=0,"!!! Vyplň DATUM !!!",IF(AND(Tabulka2[[#This Row],[Datum]]>0,Tabulka2[[#This Row],[Firma]]=0),"!!! Vyplň FIRMU !!!",IF(AND(Tabulka2[[#This Row],[Datum]]>0,Tabulka2[[#This Row],[Firma]]>0,Tabulka2[[#This Row],[Pracovník]]=0),"!!! Vyplň PRACOVNÍKA !!!",IF(AND(Tabulka2[[#This Row],[Datum]]>0,Tabulka2[[#This Row],[Firma]]>0,Tabulka2[[#This Row],[Pracovník]]>0,Tabulka2[[#This Row],[Přítomnost / Směna]]=0),"!!! Vyplň SMĚNU !!!","")))),"") | B6: 45924 | C6: BATZ | D6: Brewinski Zbigniew | E6: =IFERROR(VLOOKUP(Tabulka2[[#This Row],[Pracovník]],DATA!A:L,5,0),"") -> 5400 | F6: N | I6: =IFERROR(VLOOKUP(Tabulka2[[#This Row],[Pracovník]],DATA!A:L,11,0),"") -> BATZ 1
A7: =IFERROR(IF(Tabulka2[[#This Row],[Datum]]=0,"!!! Vyplň DATUM !!!",IF(AND(Tabulka2[[#This Row],[Datum]]>0,Tabulka2[[#This Row],[Firma]]=0),"!!! Vyplň FIRMU !!!",IF(AND(Tabulka2[[#This Row],[Datum]]>0,Tabulka2[[#This Row],[Firma]]>0,Tabulka2[[#This Row],[Pracovník]]=0),"!!! Vyplň PRACOVNÍKA !!!",IF(AND(Tabulka2[[#This Row],[Datum]]>0,Tabulka2[[#This Row],[Firma]]>0,Tabulka2[[#This Row],[Pracovník]]>0,Tabulka2[[#This Row],[Přítomnost / Směna]]=0),"!!! Vyplň SMĚNU !!!","")))),"") | B7: 45924 | C7: BATZ | D7: Bujok Dominik | E7: =IFERROR(VLOOKUP(Tabulka2[[#This Row],[Pracovník]],DATA!A:L,5,0),"") -> 5094 | F7: R | I7: =IFERROR(VLOOKUP(Tabulka2[[#This Row],[Pracovník]],DATA!A:L,11,0),"") -> BATZ 2 | J7: Odpolední
A8: =IFERROR(IF(Tabulka2[[#This Row],[Datum]]=0,"!!! Vyplň DATUM !!!",IF(AND(Tabulka2[[#This Row],[Datum]]>0,Tabulka2[[#This Row],[Firma]]=0),"!!! Vyplň FIRMU !!!",IF(AND(Tabulka2[[#This Row],[Datum]]>0,Tabulka2[[#This Row],[Firma]]>0,Tabulka2[[#This Row],[Pracovník]]=0),"!!! Vyplň PRACOVNÍKA !!!",IF(AND(Tabulka2[[#This Row],[Datum]]>0,Tabulka2[[#This Row],[Firma]]>0,Tabulka2[[#This Row],[Pracovník]]>0,Tabulka2[[#This Row],[Přítomnost / Směna]]=0),"!!! Vyplň SMĚNU !!!","")))),"") | B8: 45924 | C8: BATZ | D8: Bury Angelika | E8: =IFERROR(VLOOKUP(Tabulka2[[#This Row],[Pracovník]],DATA!A:L,5,0),"") -> 6001 | F8: R | I8: =IFERROR(VLOOKUP(Tabulka2[[#This Row],[Pracovník]],DATA!A:L,11,0),"") -> BATZ 1
A9: =IFERROR(IF(Tabulka2[[#This Row],[Datum]]=0,"!!! Vyplň DATUM !!!",IF(AND(Tabulka2[[#This Row],[Datum]]>0,Tabulka2[[#This Row],[Firma]]=0),"!!! Vyplň FIRMU !!!",IF(AND(Tabulka2[[#This Row],[Datum]]>0,Tabulka2[[#This Row],[Firma]]>0,Tabulka2[[#This Row],[Pracovník]]=0),"!!! Vyplň PRACOVNÍKA !!!",IF(AND(Tabulka2[[#This Row],[Datum]]>0,Tabulka2[[#This Row],[Firma]]>0,Tabulka2[[#This Row],[Pracovník]]>0,Tabulka2[[#This Row],[Přítomnost / Směna]]=0),"!!! Vyplň SMĚNU !!!","")))),"") | B9: 45924 | C9: BATZ | D9: Buturla Bozena | E9: =IFERROR(VLOOKUP(Tabulka2[[#This Row],[Pracovník]],DATA!A:L,5,0),"") -> 6573 | F9: R | I9: =IFERROR(VLOOKUP(Tabulka2[[#This Row],[Pracovník]],DATA!A:L,11,0),"") -> BATZ 1
A10: =IFERROR(IF(Tabulka2[[#This Row],[Datum]]=0,"!!! Vyplň DATUM !!!",IF(AND(Tabulka2[[#This Row],[Datum]]>0,Tabulka2[[#This Row],[Firma]]=0),"!!! Vyplň FIRMU !!!",IF(AND(Tabulka2[[#This Row],[Datum]]>0,Tabulka2[[#This Row],[Firma]]>0,Tabulka2[[#This Row],[Pracovník]]=0),"!!! Vyplň PRACOVNÍKA !!!",IF(AND(Tabulka2[[#This Row],[Datum]]>0,Tabulka2[[#This Row],[Firma]]>0,Tabulka2[[#This Row],[Pracovník]]>0,Tabulka2[[#This Row],[Přítomnost / Směna]]=0),"!!! Vyplň SMĚNU !!!","")))),"") | B10: 45924 | C10: BATZ | D10: Buza Grazyna Aniela | E10: =IFERROR(VLOOKUP(Tabulka2[[#This Row],[Pracovník]],DATA!A:L,5,0),"") -> 5129 | F10: O | I10: =IFERROR(VLOOKUP(Tabulka2[[#This Row],[Pracovník]],DATA!A:L,11,0),"") -> BATZ 1
A11: =IFERROR(IF(Tabulka2[[#This Row],[Datum]]=0,"!!! Vyplň DATUM !!!",IF(AND(Tabulka2[[#This Row],[Datum]]>0,Tabulka2[[#This Row],[Firma]]=0),"!!! Vyplň FIRMU !!!",IF(AND(Tabulka2[[#This Row],[Datum]]>0,Tabulka2[[#This Row],[Firma]]>0,Tabulka2[[#This Row],[Pracovník]]=0),"!!! Vyplň PRACOVNÍKA !!!",IF(AND(Tabulka2[[#This Row],[Datum]]>0,Tabulka2[[#This Row],[Firma]]>0,Tabulka2[[#This Row],[Pracovník]]>0,Tabulka2[[#This Row],[Přítomnost / Směna]]=0),"!!! Vyplň SMĚNU !!!","")))),"") | B11: 45924 | C11: BATZ | D11: Buza Jan Ireneusz | E11: =IFERROR(VLOOKUP(Tabulka2[[#This Row],[Pracovník]],DATA!A:L,5,0),"") -> 5663 | F11: O | I11: =IFERROR(VLOOKUP(Tabulka2[[#This Row],[Pracovník]],DATA!A:L,11,0),"") -> BATZ 1
A12: =IFERROR(IF(Tabulka2[[#This Row],[Datum]]=0,"!!! Vyplň DATUM !!!",IF(AND(Tabulka2[[#This Row],[Datum]]>0,Tabulka2[[#This Row],[Firma]]=0),"!!! Vyplň FIRMU !!!",IF(AND(Tabulka2[[#This Row],[Datum]]>0,Tabulka2[[#This Row],[Firma]]>0,Tabulka2[[#This Row],[Pracovník]]=0),"!!! Vyplň PRACOVNÍKA !!!",IF(AND(Tabulka2[[#This Row],[Datum]]>0,Tabulka2[[#This Row],[Firma]]>0,Tabulka2[[#This Row],[Pracovník]]>0,Tabulka2[[#This Row],[Přítomnost / Směna]]=0),"!!! Vyplň SMĚNU !!!","")))),"") | B12: 45924 | C12: BATZ | D12: Cyrzyk Grazyna Barbara | E12: =IFERROR(VLOOKUP(Tabulka2[[#This Row],[Pracovník]],DATA!A:L,5,0),"") -> 4501 | F12: R | I12: =IFERROR(VLOOKUP(Tabulka2[[#This Row],[Pracovník]],DATA!A:L,11,0),"") -> BATZ 2
A13: =IFERROR(IF(Tabulka2[[#This Row],[Datum]]=0,"!!! Vyplň DATUM !!!",IF(AND(Tabulka2[[#This Row],[Datum]]>0,Tabulka2[[#This Row],[Firma]]=0),"!!! Vyplň FIRMU !!!",IF(AND(Tabulka2[[#This Row],[Datum]]>0,Tabulka2[[#This Row],[Firma]]>0,Tabulka2[[#This Row],[Pracovník]]=0),"!!! Vyplň PRACOVNÍKA !!!",IF(AND(Tabulka2[[#This Row],[Datum]]>0,Tabulka2[[#This Row],[Firma]]>0,Tabulka2[[#This Row],[Pracovník]]>0,Tabulka2[[#This Row],[Přítomnost / Směna]]=0),"!!! Vyplň SMĚNU !!!","")))),"") | B13: 45924 | C13: BATZ | D13: Cwiklak Robert | E13: =IFERROR(VLOOKUP(Tabulka2[[#This Row],[Pracovník]],DATA!A:L,5,0),"") -> 4936 | F13: R | I13: =IFERROR(VLOOKUP(Tabulka2[[#This Row],[Pracovník]],DATA!A:L,11,0),"") -> BATZ 1
A14: =IFERROR(IF(Tabulka2[[#This Row],[Datum]]=0,"!!! Vyplň DATUM !!!",IF(AND(Tabulka2[[#This Row],[Datum]]>0,Tabulka2[[#This Row],[Firma]]=0),"!!! Vyplň FIRMU !!!",IF(AND(Tabulka2[[#This Row],[Datum]]>0,Tabulka2[[#This Row],[Firma]]>0,Tabulka2[[#This Row],[Pracovník]]=0),"!!! Vyplň PRACOVNÍKA !!!",IF(AND(Tabulka2[[#This Row],[Datum]]>0,Tabulka2[[#This Row],[Firma]]>0,Tabulka2[[#This Row],[Pracovník]]>0,Tabulka2[[#This Row],[Přítomnost / Směna]]=0),"!!! Vyplň SMĚNU !!!","")))),"") | B14: 45924 | C14: BATZ | D14: Chodinský Rostislav | E14: =IFERROR(VLOOKUP(Tabulka2[[#This Row],[Pracovník]],DATA!A:L,5,0),"") -> 3728 | F14: R | I14: =IFERROR(VLOOKUP(Tabulka2[[#This Row],[Pracovník]],DATA!A:L,11,0),"") -> BATZ 1
A15: =IFERROR(IF(Tabulka2[[#This Row],[Datum]]=0,"!!! Vyplň DATUM !!!",IF(AND(Tabulka2[[#This Row],[Datum]]>0,Tabulka2[[#This Row],[Firma]]=0),"!!! Vyplň FIRMU !!!",IF(AND(Tabulka2[[#This Row],[Datum]]>0,Tabulka2[[#This Row],[Firma]]>0,Tabulka2[[#This Row],[Pracovník]]=0),"!!! Vyplň PRACOVNÍKA !!!",IF(AND(Tabulka2[[#This Row],[Datum]]>0,Tabulka2[[#This Row],[Firma]]>0,Tabulka2[[#This Row],[Pracovník]]>0,Tabulka2[[#This Row],[Přítomnost / Směna]]=0),"!!! Vyplň SMĚNU !!!","")))),"") | B15: 45924 | C15: BATZ | D15: Dalemula Krysztof Grzegorz | E15: =IFERROR(VLOOKUP(Tabulka2[[#This Row],[Pracovník]],DATA!A:L,5,0),"") -> 4955 | F15: O | I15: =IFERROR(VLOOKUP(Tabulka2[[#This Row],[Pracovník]],DATA!A:L,11,0),"") -> BATZ 1
A16: =IFERROR(IF(Tabulka2[[#This Row],[Datum]]=0,"!!! Vyplň DATUM !!!",IF(AND(Tabulka2[[#This Row],[Datum]]>0,Tabulka2[[#This Row],[Firma]]=0),"!!! Vyplň FIRMU !!!",IF(AND(Tabulka2[[#This Row],[Datum]]>0,Tabulka2[[#This Row],[Firma]]>0,Tabulka2[[#This Row],[Pracovník]]=0),"!!! Vyplň PRACOVNÍKA !!!",IF(AND(Tabulka2[[#This Row],[Datum]]>0,Tabulka2[[#This Row],[Firma]]>0,Tabulka2[[#This Row],[Pracovník]]>0,Tabulka2[[#This Row],[Přítomnost / Směna]]=0),"!!! Vyplň SMĚNU !!!","")))),"") | B16: 45924 | C16: BATZ | D16: Dolezych Lidia | E16: =IFERROR(VLOOKUP(Tabulka2[[#This Row],[Pracovník]],DATA!A:L,5,0),"") -> 6568 | F16: R | I16: =IFERROR(VLOOKUP(Tabulka2[[#This Row],[Pracovník]],DATA!A:L,11,0),"") -> BATZ 2
A17: =IFERROR(IF(Tabulka2[[#This Row],[Datum]]=0,"!!! Vyplň DATUM !!!",IF(AND(Tabulka2[[#This Row],[Datum]]>0,Tabulka2[[#This Row],[Firma]]=0),"!!! Vyplň FIRMU !!!",IF(AND(Tabulka2[[#This Row],[Datum]]>0,Tabulka2[[#This Row],[Firma]]>0,Tabulka2[[#This Row],[Pracovník]]=0),"!!! Vyplň PRACOVNÍKA !!!",IF(AND(Tabulka2[[#This Row],[Datum]]>0,Tabulka2[[#This Row],[Firma]]>0,Tabulka2[[#This Row],[Pracovník]]>0,Tabulka2[[#This Row],[Přítomnost / Směna]]=0),"!!! Vyplň SMĚNU !!!","")))),"") | B17: 45924 | C17: BATZ | D17: Fitrzyková Jana | E17: =IFERROR(VLOOKUP(Tabulka2[[#This Row],[Pracovník]],DATA!A:L,5,0),"") -> 3721 | F17: O | I17: =IFERROR(VLOOKUP(Tabulka2[[#This Row],[Pracovník]],DATA!A:L,11,0),"") -> BATZ 1
A18: =IFERROR(IF(Tabulka2[[#This Row],[Datum]]=0,"!!! Vyplň DATUM !!!",IF(AND(Tabulka2[[#This Row],[Datum]]>0,Tabulka2[[#This Row],[Firma]]=0),"!!! Vyplň FIRMU !!!",IF(AND(Tabulka2[[#This Row],[Datum]]>0,Tabulka2[[#This Row],[Firma]]>0,Tabulka2[[#This Row],[Pracovník]]=0),"!!! Vyplň PRACOVNÍKA !!!",IF(AND(Tabulka2[[#This Row],[Datum]]>0,Tabulka2[[#This Row],[Firma]]>0,Tabulka2[[#This Row],[Pracovník]]>0,Tabulka2[[#This Row],[Přítomnost / Směna]]=0),"!!! Vyplň SMĚNU !!!","")))),"") | B18: 45924 | C18: BATZ | D18: Gorka Grzegorz | E18: =IFERROR(VLOOKUP(Tabulka2[[#This Row],[Pracovník]],DATA!A:L,5,0),"") -> 6110 | F18: R | I18: =IFERROR(VLOOKUP(Tabulka2[[#This Row],[Pracovník]],DATA!A:L,11,0),"") -> BATZ 1
A19: =IFERROR(IF(Tabulka2[[#This Row],[Datum]]=0,"!!! Vyplň DATUM !!!",IF(AND(Tabulka2[[#This Row],[Datum]]>0,Tabulka2[[#This Row],[Firma]]=0),"!!! Vyplň FIRMU !!!",IF(AND(Tabulka2[[#This Row],[Datum]]>0,Tabulka2[[#This Row],[Firma]]>0,Tabulka2[[#This Row],[Pracovník]]=0),"!!! Vyplň PRACOVNÍKA !!!",IF(AND(Tabulka2[[#This Row],[Datum]]>0,Tabulka2[[#This Row],[Firma]]>0,Tabulka2[[#This Row],[Pracovník]]>0,Tabulka2[[#This Row],[Přítomnost / Směna]]=0),"!!! Vyplň SMĚNU !!!","")))),"") | B19: 45924 | C19: BATZ | D19: Janik-Rurarz Izabela | E19: =IFERROR(VLOOKUP(Tabulka2[[#This Row],[Pracovník]],DATA!A:L,5,0),"") -> 0 | F19: O | I19: =IFERROR(VLOOKUP(Tabulka2[[#This Row],[Pracovník]],DATA!A:L,11,0),"") -> BATZ 1
... A23: =IFERROR(IF(Tabulka2[[#This Row],[Datum]]=0,"!!! Vyplň DATUM !!!",IF(AND(Tabulka2[[#This Row],[Datum]]>0,Tabulka2[[#This Row],[Firma]]=0),"!!! Vyplň FIRMU !!!",IF(AND(Tabulka2[[#This Row],[Datum]]>0,Tabulka2[[#This Row],[Firma]]>0,Tabulka2[[#This Row],[Pracovník]]=0),"!!! Vyplň PRACOVNÍKA !!!",IF(AND(Tabulka2[[#This Row],[Datum]]>0,Tabulka2[[#This Row],[Firma]]>0,Tabulka2[[#This Row],[Pracovník]]>0,Tabulka2[[#This Row],[Přítomnost / Směna]]=0),"!!! Vyplň SMĚNU !!!","")))),"") | B23: 45924 | C23: BATZ | D23: Kowalak Krzysztof | E23: =IFERROR(VLOOKUP(Tabulka2[[#This Row],[Pracovník]],DATA!A:L,5,0),"") -> 6551 | F23: O | I23: =IFERROR(VLOOKUP(Tabulka2[[#This Row],[Pracovník]],DATA!A:L,11,0),"") -> BATZ 1
A24: =IFERROR(IF(Tabulka2[[#This Row],[Datum]]=0,"!!! Vyplň DATUM !!!",IF(AND(Tabulka2[[#This Row],[Datum]]>0,Tabulka2[[#This Row],[Firma]]=0),"!!! Vyplň FIRMU !!!",IF(AND(Tabulka2[[#This Row],[Datum]]>0,Tabulka2[[#This Row],[Firma]]>0,Tabulka2[[#This Row],[Pracovník]]=0),"!!! Vyplň PRACOVNÍKA !!!",IF(AND(Tabulka2[[#This Row],[Datum]]>0,Tabulka2[[#This Row],[Firma]]>0,Tabulka2[[#This Row],[Pracovník]]>0,Tabulka2[[#This Row],[Přítomnost / Směna]]=0),"!!! Vyplň SMĚNU !!!","")))),"") | B24: 45924 | C24: BATZ | D24: Kozielski Kozielski Andrzej Jozef | E24: =IFERROR(VLOOKUP(Tabulka2[[#This Row],[Pracovník]],DATA!A:L,5,0),"") -> 5665 | F24: A | G24: Nemoc | I24: =IFERROR(VLOOKUP(Tabulka2[[#This Row],[Pracovník]],DATA!A:L,11,0),"") -> BATZ 1
A25: =IFERROR(IF(Tabulka2[[#This Row],[Datum]]=0,"!!! Vyplň DATUM !!!",IF(AND(Tabulka2[[#This Row],[Datum]]>0,Tabulka2[[#This Row],[Firma]]=0),"!!! Vyplň FIRMU !!!",IF(AND(Tabulka2[[#This Row],[Datum]]>0,Tabulka2[[#This Row],[Firma]]>0,Tabulka2[[#This Row],[Pracovník]]=0),"!!! Vyplň PRACOVNÍKA !!!",IF(AND(Tabulka2[[#This Row],[Datum]]>0,Tabulka2[[#This Row],[Firma]]>0,Tabulka2[[#This Row],[Pracovník]]>0,Tabulka2[[#This Row],[Přítomnost / Směna]]=0),"!!! Vyplň SMĚNU !!!","")))),"") | B25: 45924 | C25: BATZ | D25: Krensel Maria | E25: =IFERROR(VLOOKUP(Tabulka2[[#This Row],[Pracovník]],DATA!A:L,5,0),"") -> 2463 | F25: N | I25: =IFERROR(VLOOKUP(Tabulka2[[#This Row],[Pracovník]],DATA!A:L,11,0),"") -> Vlastní auto
A26: =IFERROR(IF(Tabulka2[[#This Row],[Datum]]=0,"!!! Vyplň DATUM !!!",IF(AND(Tabulka2[[#This Row],[Datum]]>0,Tabulka2[[#This Row],[Firma]]=0),"!!! Vyplň FIRMU !!!",IF(AND(Tabulka2[[#This Row],[Datum]]>0,Tabulka2[[#This Row],[Firma]]>0,Tabulka2[[#This Row],[Pracovník]]=0),"!!! Vyplň PRACOVNÍKA !!!",IF(AND(Tabulka2[[#This Row],[Datum]]>0,Tabulka2[[#This Row],[Firma]]>0,Tabulka2[[#This Row],[Pracovník]]>0,Tabulka2[[#This Row],[Přítomnost / Směna]]=0),"!!! Vyplň SMĚNU !!!","")))),"") | B26: 45924 | C26: BATZ | D26: Krótki Gabriel | E26: =IFERROR(VLOOKUP(Tabulka2[[#This Row],[Pracovník]],DATA!A:L,5,0),"") -> 6536 | F26: N | I26: =IFERROR(VLOOKUP(Tabulka2[[#This Row],[Pracovník]],DATA!A:L,11,0),"") -> BATZ 2
A27: =IFERROR(IF(Tabulka2[[#This Row],[Datum]]=0,"!!! Vyplň DATUM !!!",IF(AND(Tabulka2[[#This Row],[Datum]]>0,Tabulka2[[#This Row],[Firma]]=0),"!!! Vyplň FIRMU !!!",IF(AND(Tabulka2[[#This Row],[Datum]]>0,Tabulka2[[#This Row],[Firma]]>0,Tabulka2[[#This Row],[Pracovník]]=0),"!!! Vyplň PRACOVNÍKA !!!",IF(AND(Tabulka2[[#This Row],[Datum]]>0,Tabulka2[[#This Row],[Firma]]>0,Tabulka2[[#This Row],[Pracovník]]>0,Tabulka2[[#This Row],[Přítomnost / Směna]]=0),"!!! Vyplň SMĚNU !!!","")))),"") | B27: 45924 | C27: BATZ | D27: Kuklińska Malgorzata | E27: =IFERROR(VLOOKUP(Tabulka2[[#This Row],[Pracovník]],DATA!A:L,5,0),"") -> 4748 | F27: A | G27: Nemoc | I27: =IFERROR(VLOOKUP(Tabulka2[[#This Row],[Pracovník]],DATA!A:L,11,0),"") -> BATZ 1
A28: =IFERROR(IF(Tabulka2[[#This Row],[Datum]]=0,"!!! Vyplň DATUM !!!",IF(AND(Tabulka2[[#This Row],[Datum]]>0,Tabulka2[[#This Row],[Firma]]=0),"!!! Vyplň FIRMU !!!",IF(AND(Tabulka2[[#This Row],[Datum]]>0,Tabulka2[[#This Row],[Firma]]>0,Tabulka2[[#This Row],[Pracovník]]=0),"!!! Vyplň PRACOVNÍKA !!!",IF(AND(Tabulka2[[#This Row],[Datum]]>0,Tabulka2[[#This Row],[Firma]]>0,Tabulka2[[#This Row],[Pracovník]]>0,Tabulka2[[#This Row],[Přítomnost / Směna]]=0),"!!! Vyplň SMĚNU !!!","")))),"") | B28: 45924 | C28: BATZ | D28: Machnik Weronika | E28: =IFERROR(VLOOKUP(Tabulka2[[#This Row],[Pracovník]],DATA!A:L,5,0),"") -> 6077 | F28: A | G28: Nemoc | I28: =IFERROR(VLOOKUP(Tabulka2[[#This Row],[Pracovník]],DATA!A:L,11,0),"") -> BATZ 2 | K28: ukončení k 30.9.2025
A29: =IFERROR(IF(Tabulka2[[#This Row],[Datum]]=0,"!!! Vyplň DATUM !!!",IF(AND(Tabulka2[[#This Row],[Datum]]>0,Tabulka2[[#This Row],[Firma]]=0),"!!! Vyplň FIRMU !!!",IF(AND(Tabulka2[[#This Row],[Datum]]>0,Tabulka2[[#This Row],[Firma]]>0,Tabulka2[[#This Row],[Pracovník]]=0),"!!! Vyplň PRACOVNÍKA !!!",IF(AND(Tabulka2[[#This Row],[Datum]]>0,Tabulka2[[#This Row],[Firma]]>0,Tabulka2[[#This Row],[Pracovník]]>0,Tabulka2[[#This Row],[Přítomnost / Směna]]=0),"!!! Vyplň SMĚNU !!!","")))),"") | B29: 45924 | C29: BATZ | D29: Marczak Joanna | E29: =IFERROR(VLOOKUP(Tabulka2[[#This Row],[Pracovník]],DATA!A:L,5,0),"") -> 6574 | F29: N | I29: =IFERROR(VLOOKUP(Tabulka2[[#This Row],[Pracovník]],DATA!A:L,11,0),"") -> BATZ 1
A30: =IFERROR(IF(Tabulka2[[#This Row],[Datum]]=0,"!!! Vyplň DATUM !!!",IF(AND(Tabulka2[[#This Row],[Datum]]>0,Tabulka2[[#This Row],[Firma]]=0),"!!! Vyplň FIRMU !!!",IF(AND(Tabulka2[[#This Row],[Datum]]>0,Tabulka2[[#This Row],[Firma]]>0,Tabulka2[[#This Row],[Pracovník]]=0),"!!! Vyplň PRACOVNÍKA !!!",IF(AND(Tabulka2[[#This Row],[Datum]]>0,Tabulka2[[#This Row],[Firma]]>0,Tabulka2[[#This Row],[Pracovník]]>0,Tabulka2[[#This Row],[Přítomnost / Směna]]=0),"!!! Vyplň SMĚNU !!!","")))),"") | B30: 45924 | C30: BATZ | D30: Marczak Maria Katarzyna | E30: =IFERROR(VLOOKUP(Tabulka2[[#This Row],[Pracovník]],DATA!A:L,5,0),"") -> 4720 | F30: R | I30: =IFERROR(VLOOKUP(Tabulka2[[#This Row],[Pracovník]],DATA!A:L,11,0),"") -> BATZ 2
A31: =IFERROR(IF(Tabulka2[[#This Row],[Datum]]=0,"!!! Vyplň DATUM !!!",IF(AND(Tabulka2[[#This Row],[Datum]]>0,Tabulka2[[#This Row],[Firma]]=0),"!!! Vyplň FIRMU !!!",IF(AND(Tabulka2[[#This Row],[Datum]]>0,Tabulka2[[#This Row],[Firma]]>0,Tabulka2[[#This Row],[Pracovník]]=0),"!!! Vyplň PRACOVNÍKA !!!",IF(AND(Tabulka2[[#This Row],[Datum]]>0,Tabulka2[[#This Row],[Firma]]>0,Tabulka2[[#This Row],[Pracovník]]>0,Tabulka2[[#This Row],[Přítomnost / Směna]]=0),"!!! Vyplň SMĚNU !!!","")))),"") | B31: 45924 | C31: BATZ | D31: Marekwica Adrian | E31: =IFERROR(VLOOKUP(Tabulka2[[#This Row],[Pracovník]],DATA!A:L,5,0),"") -> 6409 | F31: R | I31: =IFERROR(VLOOKUP(Tabulka2[[#This Row],[Pracovník]],DATA!A:L,11,0),"") -> Vlastní auto
A32: =IFERROR(IF(Tabulka2[[#This Row],[Datum]]=0,"!!! Vyplň DATUM !!!",IF(AND(Tabulka2[[#This Row],[Datum]]>0,Tabulka2[[#This Row],[Firma]]=0),"!!! Vyplň FIRMU !!!",IF(AND(Tabulka2[[#This Row],[Datum]]>0,Tabulka2[[#This Row],[Firma]]>0,Tabulka2[[#This Row],[Pracovník]]=0),"!!! Vyplň PRACOVNÍKA !!!",IF(AND(Tabulka2[[#This Row],[Datum]]>0,Tabulka2[[#This Row],[Firma]]>0,Tabulka2[[#This Row],[Pracovník]]>0,Tabulka2[[#This Row],[Přítomnost / Směna]]=0),"!!! Vyplň SMĚNU !!!","")))),"") | B32: 45924 | C32: BATZ | D32: Matusiak Orfeusz Marek | E32: =IFERROR(VLOOKUP(Tabulka2[[#This Row],[Pracovník]],DATA!A:L,5,0),"") -> 3396 | F32: N | I32: =IFERROR(VLOOKUP(Tabulka2[[#This Row],[Pracovník]],DATA!A:L,11,0),"") -> BATZ 1
A33: =IFERROR(IF(Tabulka2[[#This Row],[Datum]]=0,"!!! Vyplň DATUM !!!",IF(AND(Tabulka2[[#This Row],[Datum]]>0,Tabulka2[[#This Row],[Firma]]=0),"!!! Vyplň FIRMU !!!",IF(AND(Tabulka2[[#This Row],[Datum]]>0,Tabulka2[[#This Row],[Firma]]>0,Tabulka2[[#This Row],[Pracovník]]=0),"!!! Vyplň PRACOVNÍKA !!!",IF(AND(Tabulka2[[#This Row],[Datum]]>0,Tabulka2[[#This Row],[Firma]]>0,Tabulka2[[#This Row],[Pracovník]]>0,Tabulka2[[#This Row],[Přítomnost / Směna]]=0),"!!! Vyplň SMĚNU !!!","")))),"") | B33: 45924 | C33: BATZ | D33: Meyer Beata | E33: =IFERROR(VLOOKUP(Tabulka2[[#This Row],[Pracovník]],DATA!A:L,5,0),"") -> 6376 | F33: N | I33: =IFERROR(VLOOKUP(Tabulka2[[#This Row],[Pracovník]],DATA!A:L,11,0),"") -> BATZ 2
A34: =IFERROR(IF(Tabulka2[[#This Row],[Datum]]=0,"!!! Vyplň DATUM !!!",IF(AND(Tabulka2[[#This Row],[Datum]]>0,Tabulka2[[#This Row],[Firma]]=0),"!!! Vyplň FIRMU !!!",IF(AND(Tabulka2[[#This Row],[Datum]]>0,Tabulka2[[#This Row],[Firma]]>0,Tabulka2[[#This Row],[Pracovník]]=0),"!!! Vyplň PRACOVNÍKA !!!",IF(AND(Tabulka2[[#This Row],[Datum]]>0,Tabulka2[[#This Row],[Firma]]>0,Tabulka2[[#This Row],[Pracovník]]>0,Tabulka2[[#This Row],[Přítomnost / Směna]]=0),"!!! Vyplň SMĚNU !!!","")))),"") | B34: 45924 | C34: BATZ | D34: Michalec Regina | E34: =IFERROR(VLOOKUP(Tabulka2[[#This Row],[Pracovník]],DATA!A:L,5,0),"") -> 5014 | F34: N | I34: =IFERROR(VLOOKUP(Tabulka2[[#This Row],[Pracovník]],DATA!A:L,11,0),"") -> BATZ 2
A35: =IFERROR(IF(Tabulka2[[#This Row],[Datum]]=0,"!!! Vyplň DATUM !!!",IF(AND(Tabulka2[[#This Row],[Datum]]>0,Tabulka2[[#This Row],[Firma]]=0),"!!! Vyplň FIRMU !!!",IF(AND(Tabulka2[[#This Row],[Datum]]>0,Tabulka2[[#This Row],[Firma]]>0,Tabulka2[[#This Row],[Pracovník]]=0),"!!! Vyplň PRACOVNÍKA !!!",IF(AND(Tabulka2[[#This Row],[Datum]]>0,Tabulka2[[#This Row],[Firma]]>0,Tabulka2[[#This Row],[Pracovník]]>0,Tabulka2[[#This Row],[Přítomnost / Směna]]=0),"!!! Vyplň SMĚNU !!!","")))),"") | B35: 45924 | C35: BATZ | D35: Mottlová Markéta | E35: =IFERROR(VLOOKUP(Tabulka2[[#This Row],[Pracovník]],DATA!A:L,5,0),"") -> 3369 | F35: R | I35: =IFERROR(VLOOKUP(Tabulka2[[#This Row],[Pracovník]],DATA!A:L,11,0),"") -> BATZ 1
A36: =IFERROR(IF(Tabulka2[[#This Row],[Datum]]=0,"!!! Vyplň DATUM !!!",IF(AND(Tabulka2[[#This Row],[Datum]]>0,Tabulka2[[#This Row],[Firma]]=0),"!!! Vyplň FIRMU !!!",IF(AND(Tabulka2[[#This Row],[Datum]]>0,Tabulka2[[#This Row],[Firma]]>0,Tabulka2[[#This Row],[Pracovník]]=0),"!!! Vyplň PRACOVNÍKA !!!",IF(AND(Tabulka2[[#This Row],[Datum]]>0,Tabulka2[[#This Row],[Firma]]>0,Tabulka2[[#This Row],[Pracovník]]>0,Tabulka2[[#This Row],[Přítomnost / Směna]]=0),"!!! Vyplň SMĚNU !!!","")))),"") | B36: 45924 | C36: BATZ | D36: Nowak Martyna | E36: =IFERROR(VLOOKUP(Tabulka2[[#This Row],[Pracovník]],DATA!A:L,5,0),"") -> 6576 | F36: R | I36: =IFERROR(VLOOKUP(Tabulka2[[#This Row],[Pracovník]],DATA!A:L,11,0),"") -> BATZ 1
A37: =IFERROR(IF(Tabulka2[[#This Row],[Datum]]=0,"!!! Vyplň DATUM !!!",IF(AND(Tabulka2[[#This Row],[Datum]]>0,Tabulka2[[#This Row],[Firma]]=0),"!!! Vyplň FIRMU !!!",IF(AND(Tabulka2[[#This Row],[Datum]]>0,Tabulka2[[#This Row],[Firma]]>0,Tabulka2[[#This Row],[Pracovník]]=0),"!!! Vyplň PRACOVNÍKA !!!",IF(AND(Tabulka2[[#This Row],[Datum]]>0,Tabulka2[[#This Row],[Firma]]>0,Tabulka2[[#This Row],[Pracovník]]>0,Tabulka2[[#This Row],[Přítomnost / Směna]]=0),"!!! Vyplň SMĚNU !!!","")))),"") | B37: 45924 | C37: BATZ | D37: Opyd Marzena | E37: =IFERROR(VLOOKUP(Tabulka2[[#This Row],[Pracovník]],DATA!A:L,5,0),"") -> 6352 | F37: O | I37: =IFERROR(VLOOKUP(Tabulka2[[#This Row],[Pracovník]],DATA!A:L,11,0),"") -> BATZ 1
A38: =IFERROR(IF(Tabulka2[[#This Row],[Datum]]=0,"!!! Vyplň DATUM !!!",IF(AND(Tabulka2[[#This Row],[Datum]]>0,Tabulka2[[#This Row],[Firma]]=0),"!!! Vyplň FIRMU !!!",IF(AND(Tabulka2[[#This Row],[Datum]]>0,Tabulka2[[#This Row],[Firma]]>0,Tabulka2[[#This Row],[Pracovník]]=0),"!!! Vyplň PRACOVNÍKA !!!",IF(AND(Tabulka2[[#This Row],[Datum]]>0,Tabulka2[[#This Row],[Firma]]>0,Tabulka2[[#This Row],[Pracovník]]>0,Tabulka2[[#This Row],[Přítomnost / Směna]]=0),"!!! Vyplň SMĚNU !!!","")))),"") | B38: 45924 | C38: BATZ | D38: Ostafin Andrzej Zbigniew | E38: =IFERROR(VLOOKUP(Tabulka2[[#This Row],[Pracovník]],DATA!A:L,5,0),"") -> 5009 | F38: R | I38: =IFERROR(VLOOKUP(Tabulka2[[#This Row],[Pracovník]],DATA!A:L,11,0),"") -> BATZ 1
A39: =IFERROR(IF(Tabulka2[[#This Row],[Datum]]=0,"!!! Vyplň DATUM !!!",IF(AND(Tabulka2[[#This Row],[Datum]]>0,Tabulka2[[#This Row],[Firma]]=0),"!!! Vyplň FIRMU !!!",IF(AND(Tabulka2[[#This Row],[Datum]]>0,Tabulka2[[#This Row],[Firma]]>0,Tabulka2[[#This Row],[Pracovník]]=0),"!!! Vyplň PRACOVNÍKA !!!",IF(AND(Tabulka2[[#This Row],[Datum]]>0,Tabulka2[[#This Row],[Firma]]>0,Tabulka2[[#This Row],[Pracovník]]>0,Tabulka2[[#This Row],[Přítomnost / Směna]]=0),"!!! Vyplň SMĚNU !!!","")))),"") | B39: 45924 | C39: BATZ | D39: Ostafin Hanna | E39: =IFERROR(VLOOKUP(Tabulka2[[#This Row],[Pracovník]],DATA!A:L,5,0),"") -> 6251 | F39: A | G39: Nemoc | I39: =IFERROR(VLOOKUP(Tabulka2[[#This Row],[Pracovník]],DATA!A:L,11,0),"") -> BATZ 1
A40: =IFERROR(IF(Tabulka2[[#This Row],[Datum]]=0,"!!! Vyplň DATUM !!!",IF(AND(Tabulka2[[#This Row],[Datum]]>0,Tabulka2[[#This Row],[Firma]]=0),"!!! Vyplň FIRMU !!!",IF(AND(Tabulka2[[#This Row],[Datum]]>0,Tabulka2[[#This Row],[Firma]]>0,Tabulka2[[#This Row],[Pracovník]]=0),"!!! Vyplň PRACOVNÍKA !!!",IF(AND(Tabulka2[[#This Row],[Datum]]>0,Tabulka2[[#This Row],[Firma]]>0,Tabulka2[[#This Row],[Pracovník]]>0,Tabulka2[[#This Row],[Přítomnost / Směna]]=0),"!!! Vyplň SMĚNU !!!","")))),"") | B40: 45924 | C40: BATZ | D40: Ostafin Klaudia | E40: =IFERROR(VLOOKUP(Tabulka2[[#This Row],[Pracovník]],DATA!A:L,5,0),"") -> 6507 | F40: R | I40: =IFERROR(VLOOKUP(Tabulka2[[#This Row],[Pracovník]],DATA!A:L,11,0),"") -> BATZ 1
A41: =IFERROR(IF(Tabulka2[[#This Row],[Datum]]=0,"!!! Vyplň DATUM !!!",IF(AND(Tabulka2[[#This Row],[Datum]]>0,Tabulka2[[#This Row],[Firma]]=0),"!!! Vyplň FIRMU !!!",IF(AND(Tabulka2[[#This Row],[Datum]]>0,Tabulka2[[#This Row],[Firma]]>0,Tabulka2[[#This Row],[Pracovník]]=0),"!!! Vyplň PRACOVNÍKA !!!",IF(AND(Tabulka2[[#This Row],[Datum]]>0,Tabulka2[[#This Row],[Firma]]>0,Tabulka2[[#This Row],[Pracovník]]>0,Tabulka2[[#This Row],[Přítomnost / Směna]]=0),"!!! Vyplň SMĚNU !!!","")))),"") | B41: 45924 | C41: BATZ | D41: Paduch Andrzej | E41: =IFERROR(VLOOKUP(Tabulka2[[#This Row],[Pracovník]],DATA!A:L,5,0),"") -> 6346 | F41: R | I41: =IFERROR(VLOOKUP(Tabulka2[[#This Row],[Pracovník]],DATA!A:L,11,0),"") -> BATZ 1
A42: =IFERROR(IF(Tabulka2[[#This Row],[Datum]]=0,"!!! Vyplň DATUM !!!",IF(AND(Tabulka2[[#This Row],[Datum]]>0,Tabulka2[[#This Row],[Firma]]=0),"!!! Vyplň FIRMU !!!",IF(AND(Tabulka2[[#This Row],[Datum]]>0,Tabulka2[[#This Row],[Firma]]>0,Tabulka2[[#This Row],[Pracovník]]=0),"!!! Vyplň PRACOVNÍKA !!!",IF(AND(Tabulka2[[#This Row],[Datum]]>0,Tabulka2[[#This Row],[Firma]]>0,Tabulka2[[#This Row],[Pracovník]]>0,Tabulka2[[#This Row],[Přítomnost / Směna]]=0),"!!! Vyplň SMĚNU !!!","")))),"") | B42: 45924 | C42: BATZ | D42: Pajor Jolanta Wanda | E42: =IFERROR(VLOOKUP(Tabulka2[[#This Row],[Pracovník]],DATA!A:L,5,0),"") -> 4972 | F42: R | I42: =IFERROR(VLOOKUP(Tabulka2[[#This Row],[Pracovník]],DATA!A:L,11,0),"") -> BATZ 2
A43: =IFERROR(IF(Tabulka2[[#This Row],[Datum]]=0,"!!! Vyplň DATUM !!!",IF(AND(Tabulka2[[#This Row],[Datum]]>0,Tabulka2[[#This Row],[Firma]]=0),"!!! Vyplň FIRMU !!!",IF(AND(Tabulka2[[#This Row],[Datum]]>0,Tabulka2[[#This Row],[Firma]]>0,Tabulka2[[#This Row],[Pracovník]]=0),"!!! Vyplň PRACOVNÍKA !!!",IF(AND(Tabulka2[[#This Row],[Datum]]>0,Tabulka2[[#This Row],[Firma]]>0,Tabulka2[[#This Row],[Pracovník]]>0,Tabulka2[[#This Row],[Přítomnost / Směna]]=0),"!!! Vyplň SMĚNU !!!","")))),"") | B43: 45924 | C43: BATZ | D43: Piechaczek Agnieszka | E43: =IFERROR(VLOOKUP(Tabulka2[[#This Row],[Pracovník]],DATA!A:L,5,0),"") -> 2230 | F43: R | I43: =IFERROR(VLOOKUP(Tabulka2[[#This Row],[Pracovník]],DATA!A:L,11,0),"") -> BATZ 1
...

Sheet PIVOT
B2: Počet z Přítomnost / Směna | C2: Popisky sloupců
C3: IX | H3: X
B4: Popisky řádků | C4: 45924 | D4: 45925 | E4: 45926 | F4: 45929 | G4: 45930 | H4: 45931 | I4: 45932 | J4: 45933 | K4: 45936 | L4: 45937
B5: BATZ | C5: 5 | D5: 10 | E5: 18 | F5: 39 | G5: 70 | H5: 6 | I5: 10 | J5: 10 | K5: 13 | L5: 10
B6: THERMA | C6: 1 | D6: 1 | E6: 1 | G6: 4 | H6: 1 | I6: 1 | J6: 1 | K6: 1 | L6: 1
B7: DONGHEE | C7: 4 | D7: 5 | E7: 8 | F7: 42 | G7: 40 | H7: 9 | I7: 1 | J7: 1
B8: DSC | C8: 5 | D8: 5 | E8: 7 | F8: 90 | G8: 9 | H8: 7 | I8: 6 | J8: 5 | K8: 9 | L8: 7
B9: Celkový součet | C9: 15 | D9: 21 | E9: 34 | F9: 171 | G9: 123 | H9: 23 | I9: 18 | J9: 17 | K9: 23 | L9: 18
