Workbook

Sheet zastavky
A1: id | B1: spz | C1: oznaceni | D1: zastavka | E1: vyber
A2: 1 | B2: SK822SC SCANIA | C2: BATZ - Szeroka / Jastrzębie Zdrój / Wodzislaw Sl. | D2: 1 Szeroka ul. Rybnicka | E2: =B2 & " " & C2 & " " & D2 -> SK822SC SCANIA BATZ - Szeroka / Jastrzębie Zdrój / Wodzislaw Sl. 1 Szeroka ul. Rybnicka | F2: =A2 -> 1
A3: 2 | B3: SK822SC SCANIA | C3: BATZ - Szeroka / Jastrzębie Zdrój / Wodzislaw Sl. | D3: 2 Szeroka - Biedronka | E3: =B3 & " " & C3 & " " & D3 -> SK822SC SCANIA BATZ - Szeroka / Jastrzębie Zdrój / Wodzislaw Sl. 2 Szeroka - Biedronka | F3: =A3 -> 2
A4: 3 | B4: SK822SC SCANIA | C4: BATZ - Szeroka / Jastrzębie Zdrój / Wodzislaw Sl. | D4: 3 Szeroka - Wasbruck | E4: =B4 & " " & C4 & " " & D4 -> SK822SC SCANIA BATZ - Szeroka / Jastrzębie Zdrój / Wodzislaw Sl. 3 Szeroka - Wasbruck | F4: =A4 -> 3
A5: 4 | B5: SK822SC SCANIA | C5: BATZ - Szeroka / Jastrzębie Zdrój / Wodzislaw Sl. | D5: 4 Jastr.Zd. - Pszczyńska/Rybnicka | E5: =B5 & " " & C5 & " " & D5 -> SK822SC SCANIA BATZ - Szeroka / Jastrzębie Zdrój / Wodzislaw Sl. 4 Jastr.Zd. - Pszczyńska/Rybnicka | F5: =A5 -> 4
A6: 5 | B6: SPRINTER / OPEL | C6: BATZ - Źory / Cieszyn | D6: Źory - Sąd Rejonowy | E6: =B6 & " " & C6 & " " & D6 -> SPRINTER / OPEL BATZ - Źory / Cieszyn Źory - Sąd Rejonowy | F6: =A6 -> 5
A7: 6 | B7: SPRINTER / OPEL | C7: BATZ - Źory / Cieszyn | D7: Źory - Bajerowka | E7: =B7 & " " & C7 & " " & D7 -> SPRINTER / OPEL BATZ - Źory / Cieszyn Źory - Bajerowka | F7: =A7 -> 6
A8: 7 | B8: SPRINTER / OPEL | C8: BATZ - Źory / Cieszyn | D8: Ruptawa - Cisówka | E8: =B8 & " " & C8 & " " & D8 -> SPRINTER / OPEL BATZ - Źory / Cieszyn Ruptawa - Cisówka | F8: =A8 -> 7
A9: 9 | B9: SPRINTER / OPEL | C9: BATZ - Źory / Cieszyn | D9: Zebrzydowice Ośrodek Zdrowia | E9: =B9 & " " & C9 & " " & D9 -> SPRINTER / OPEL BATZ - Źory / Cieszyn Zebrzydowice Ośrodek Zdrowia | F9: =A9 -> 9
A10: 10 | B10: SPRINTER / OPEL | C10: BATZ - Źory / Cieszyn | D10: Zebrzydowice Rondo | E10: =B10 & " " & C10 & " " & D10 -> SPRINTER / OPEL BATZ - Źory / Cieszyn Zebrzydowice Rondo | F10: =A10 -> 10
A11: 11 | B11: SPRINTER / OPEL | C11: BATZ - Źory / Cieszyn | D11: Kończyce Małe | E11: =B11 & " " & C11 & " " & D11 -> SPRINTER / OPEL BATZ - Źory / Cieszyn Kończyce Małe | F11: =A11 -> 11
A12: 12 | B12: SPRINTER / OPEL | C12: BATZ - Źory / Cieszyn | D12: Hażlach za rondo Crab | E12: =B12 & " " & C12 & " " & D12 -> SPRINTER / OPEL BATZ - Źory / Cieszyn Hażlach za rondo Crab | F12: =A12 -> 12
A13: 13 | B13: SPRINTER / OPEL | C13: BATZ - Źory / Cieszyn | D13: Hażlach obok GASTROMANIA | E13: =B13 & " " & C13 & " " & D13 -> SPRINTER / OPEL BATZ - Źory / Cieszyn Hażlach obok GASTROMANIA | F13: =A13 -> 13
... A171: 171 | B171: Oles | C171: DSC | D171: Źory - Zegar, aleja Niepodległości | E171: =B171 & " " & C171 & " " & D171 -> Oles DSC Źory - Zegar, aleja Niepodległości | F171: =A171 -> 171

Sheet zamestnanci
A1: id | B1: os_cislo | C1: prijmeni | D1: jmeno | E1: rfid | F1: nastup | G1: telefon | H1: adresa | I1: firma | J1: smena | K1: nepritomnost | L1: aktivni | M1: zastavka
A2: 1 | B2: 4984 | C2: Koblanski | D2: Daniel Roman | E2: 0001932486 | F2: =IF(M2<>"",VLOOKUP(M2,zastavky!E:F,2,FALSE),"") | G2: 48661131885 | H2: Rzemieslnicza 16, Marklowice, 44-321 | I2: 1 | J2: R | L2: 1
A3: 2 | B3: 4832 | C3: Plusa | D3: Jolanta Anastazja | E3: 0001812666 | F3: =IF(M3<>"",VLOOKUP(M3,zastavky!E:F,2,FALSE),"") | G3: 48579875413 | H3: Wolnosci 106, Wodzislaw Slaski, 44-300 | I3: 1 | J3: R | L3: 1
A4: 3 | B4: 4821 | C4: Lapczyk | D4: Wiktoria Monika | E4: 0001203587 | F4: =IF(M4<>"",VLOOKUP(M4,zastavky!E:F,2,FALSE),"") | G4: 48570354807 | H4: Stanislawa Moniuszki 24/57, Cieszyn, 43-400 | I4: 1 | J4: R | L4: 1
A5: 4 | B5: 4824 | C5: Siemieniec | D5: Mirela Malgorzata | E5: 0001319249 | F5: =IF(M5<>"",VLOOKUP(M5,zastavky!E:F,2,FALSE),"") | G5: 48534420008 | H5: Generala Sikorskiego 10, Gorzyce, 44-350 | I5: 1 | J5: R | L5: 1
A6: 5 | B6: 4816 | C6: Tkocz | D6: Grazyna | E6: 0001348553 | F6: =IF(M6<>"",VLOOKUP(M6,zastavky!E:F,2,FALSE),"") | G6: 48780473033 | H6: Rynek 19/4, Wodzislaw Slaski, 44-300 | I6: 1 | J6: R | L6: 1
A7: 6 | B7: 4823 | C7: Tomala | D7: Sabina Agata | E7: 0001213514 | F7: =IF(M7<>"",VLOOKUP(M7,zastavky!E:F,2,FALSE),"") | G7: 48731071831 | H7: Truchana 36/12, Chorzow, 41-500 | I7: 1 | J7: R | L7: 1
A8: 7 | B8: 5139 | C8: Wisniewski | D8: Andrzej Jaroslaw | E8: 0001815983 | F8: =IF(M8<>"",VLOOKUP(M8,zastavky!E:F,2,FALSE),"") | G8: 48577599086 | H8: Jana Kilinskiego 6, Marklowice, 44-321 | I8: 1 | J8: R | L8: 1
A9: 8 | B9: 4820 | C9: Zdunek | D9: Patrycja | E9: 0003356249 | F9: =IF(M9<>"",VLOOKUP(M9,zastavky!E:F,2,FALSE),"") | G9: 48535337339 | H9: Stanislawa Moniuszki 24/57, Cieszyn, 43-400 | I9: 1 | J9: R | L9: 1
A10: 9 | B10: 5178 | C10: Birka | D10: Jan | E10: 0012951123 | F10: =IF(M10<>"",VLOOKUP(M10,zastavky!E:F,2,FALSE),"") | G10: 735 826 676 | H10: Masarykovo nám. 1/1, Nový Jičín, 741 01, CZ | I10: 2 | J10: R | L10: 1
A11: 10 | B11: 5234 | C11: Bogdanska | D11: Malgorzata Beata | E11: 0013073154 | F11: =IF(M11<>"",VLOOKUP(M11,zastavky!E:F,2,FALSE),"") | G11: +48 503 935 531 | H11: 26 Marca 42/47, Wodzislaw Slaski, 44-300, PL | I11: 2 | J11: R | L11: 1
A12: 11 | B12: 3415 | C12: Boruszka | D12: Aneta Barbara | E12: 0012989719 | F12: =IF(M12<>"",VLOOKUP(M12,zastavky!E:F,2,FALSE),"") | G12: +48 605 522 989 | H12: os. 1000-lecia 15a/11, Jastrzebie-Zdroj, 44-268, PL | I12: 2 | J12: R | L12: 1
A13: 12 | B13: 3428 | C13: Cieslak | D13: Bogdan Cezary | E13: 0012037325 | F13: =IF(M13<>"",VLOOKUP(M13,zastavky!E:F,2,FALSE),"") | G13: +48 883 115 857 | H13: Polna 22C m.10, Pawlowice, 43-251, PL | I13: 2 | J13: R | L13: 1
... A91: 90 | B91: 2069 | C91: Debner | D91: Karolina | E91: 0301165689 | F91: =IF(M91<>"",VLOOKUP(M91,zastavky!E:F,2,FALSE),"") | G91: 48 739 218 695 | H91: Promienna 5/201, Zory, 44-240 | I91: 1 | J91: R | L91: 1
A92: 91 | B92: 2230 | C92: Piechaczek | D92: Agnieszka | E92: 0272698616 | F92: =IF(M92<>"",VLOOKUP(M92,zastavky!E:F,2,FALSE),"") | H92: Wiejska 21, Jastrzebie-Zdroj, 44-338 | I92: 1 | J92: R | L92: 1
A93: 92 | B93: 2945 | C93: Francová | D93: Karolína | E93: 0289821261 | F93: =IF(M93<>"",VLOOKUP(M93,zastavky!E:F,2,FALSE),"") | G93: 770 664 657 | H93: Hrnčířská 2003, Rožnov pod Radhoštěm, 756 61 | I93: 1 | J93: R | L93: 1
A94: 93 | B94: 5175 | C94: Wywiol | D94: Romeusz | E94: 0315321918 | F94: =IF(M94<>"",VLOOKUP(M94,zastavky!E:F,2,FALSE),"") | G94: 48 574 677 081 | H94: Turystyczna 1, Jastrzebie-Zdrój, 44-335 | I94: 1 | J94: R | L94: 1
A95: 94 | B95: 3257 | C95: Starzyczny | D95: Joanna | E95: 0272698647 | F95: =IF(M95<>"",VLOOKUP(M95,zastavky!E:F,2,FALSE),"") | G95: 48 693 474 209 | H95: Wiejska 9 A m.1, Jastrzebie-Zdrój, 44-338 | I95: 1 | J95: R | L95: 1
A96: 95 | B96: 3369 | C96: Mottlová | D96: Markéta | E96: 0315321940 | F96: =IF(M96<>"",VLOOKUP(M96,zastavky!E:F,2,FALSE),"") | G96: 720 578 148 | H96: Závodní 409/53, Ostrava - Hrabůvka, 700 30 | I96: 1 | J96: R | L96: 1
A97: 96 | B97: 3078 | C97: Niznik | D97: Boguslaw | E97: 0315321941 | F97: =IF(M97<>"",VLOOKUP(M97,zastavky!E:F,2,FALSE),"") | H97: Dygasinskiego 33, Pszów, 44-370 | I97: 1 | J97: R | L97: 1
A98: 97 | B98: 3721 | C98: Fitrzyková | D98: Jana | E98: 0328604658 | F98: =IF(M98<>"",VLOOKUP(M98,zastavky!E:F,2,FALSE),"") | G98: 704 188 141 | H98: Těšínská 87/281, Ostrava - Radvanice, 716 00 | I98: 1 | J98: R | L98: 1
A99: 98 | B99: 3729 | C99: Chodinský | D99: Jakub | E99: 0328608672 | F99: =IF(M99<>"",VLOOKUP(M99,zastavky!E:F,2,FALSE),"") | G99: 735 997 947 | H99: Vyškovická 447/153 , Ostrava - Výškovice, 700 30 | I99: 1 | J99: R | L99: 1
A100: 99 | B100: 3728 | C100: Chodinský | D100: Rostislav | E100: 0301165667 | F100: =IF(M100<>"",VLOOKUP(M100,zastavky!E:F,2,FALSE),"") | G100: 735 883 940 | H100: Vyškovická 447/153 , Ostrava - Výškovice, 700 30 | I100: 1 | J100: R | L100: 1
A101: 100 | B101: 4365 | C101: Šostá | D101: Ivana | E101: 0315325893 | F101: =IF(M101<>"",VLOOKUP(M101,zastavky!E:F,2,FALSE),"") | G101: 702 897 627 | H101: Hulvácká 1399/11a, Ostrava-Zábřeh , 700 30 | I101: 1 | J101: R | L101: 1
A102: 101 | B102: 3284 | C102: Matuszczyk | D102: Beata | E102: 0328608668 | F102: =IF(M102<>"",VLOOKUP(M102,zastavky!E:F,2,FALSE),"") | G102: 48 692 755 081 | H102: Górnicza 38/23, Jastrzebie-Zdroj, 44-335 | I102: 1 | J102: R | L102: 1
A103: 102 | B103: 4326 | C103: Lázoková | D103: Darina | E103: 0328608677 | F103: =IF(M103<>"",VLOOKUP(M103,zastavky!E:F,2,FALSE),"") | G103: 705 926 915 | H103: Lidická 539, Třinec - Lyžbice, 739 61 | I103: 1 | J103: R | L103: 1
A104: 103 | B104: 4442 | C104: Pajor | D104: Artur | E104: 0301165649 | F104: =IF(M104<>"",VLOOKUP(M104,zastavky!E:F,2,FALSE),"") | G104: 48 731 773 661 | H104: Gustawa Morcinka 8/6, Jastrzebie-Zdroj, 44-335 | I104: 1 | J104: R | L104: 1
A105: 104 | B105: 3871 | C105: Neudert | D105: Pavel | E105: 0370053055 | F105: =IF(M105<>"",VLOOKUP(M105,zastavky!E:F,2,FALSE),"") | G105: 704 717 533 | H105: Horní 791/3, Ostrava - Hrabůvka, 700 30 | I105: 1 | J105: R | L105: 1
A106: 105 | B106: 3920 | C106: Krzenek | D106: Ryszarda | E106: 0315325856 | F106: =IF(M106<>"",VLOOKUP(M106,zastavky!E:F,2,FALSE),"") | G106: 48 725 009 441 | H106: Skrajna 4 m.6, Cieszyn, 43-400 | I106: 1 | J106: R | L106: 1
A107: 106 | B107: 4622 | C107: Starosta | D107: Barbara | E107: 0328443818 | F107: =IF(M107<>"",VLOOKUP(M107,zastavky!E:F,2,FALSE),"") | G107: 48 735 049 358 | H107: Radlinska 147, Wodzislaw Slaski, 44-300 | I107: 1 | J107: R | L107: 1
A108: 107 | B108: 4682 | C108: Bugno | D108: Agnieszka | E108: 0289896688 | F108: =IF(M108<>"",VLOOKUP(M108,zastavky!E:F,2,FALSE),"") | G108: 48 785 427 469 | H108: Okreźna 4, Zebrzydowice, 43-410 | I108: 1 | J108: R | L108: 1
A109: 108 | B109: 4719 | C109: Paczlowski | D109: Michal | E109: 0328611446 | F109: =IF(M109<>"",VLOOKUP(M109,zastavky!E:F,2,FALSE),"") | G109: 48 535 384 403 | H109: Turnawiec 9,Turnawiec, 28-506 | I109: 1 | J109: R | L109: 1
... A216: 401 | B216: 4928 | C216: Czyź | D216: Natalia Dominika | E216: 0001867350 | F216: =IF(M216<>"",VLOOKUP(M216,zastavky!E:F,2,FALSE),"") | G216: +48 795 756 172 | H216: Wyższa Brama 17, Cieszyn, 43-400 | I216: 6 | J216: R | L216: 1
A217: 402 | B217: 49 | C217: Damis | D217: Malgorzata Maria | E217: 0009531966 | F217: =IF(M217<>"",VLOOKUP(M217,zastavky!E:F,2,FALSE),"") | H217: Jutrzenki 10, Zebrzydowice, 43-410 | I217: 6 | J217: R | L217: 1
A218: 403 | B218: 286 | C218: Dormowicz | D218: Marta Ewelina | E218: 0005160737 | F218: =IF(M218<>"",VLOOKUP(M218,zastavky!E:F,2,FALSE),"") | G218: +48 518 679 641 | H218: Czecha 4/1, Radlin, 44-310 | I218: 6 | J218: R | L218: 1
A219: 404 | B219: 4865 | C219: Dormowicz | D219: Wiktoria Marta | E219: 0003514629 | F219: =IF(M219<>"",VLOOKUP(M219,zastavky!E:F,2,FALSE),"") | G219: +48 784 009 068 | H219: Bronislawa Czecha 4/1, Radlin, 44-310 | I219: 6 | J219: R | L219: 1
A220: 405 | B220: 4610 | C220: Druzbanska | D220: Dorota Barbara | E220: 0001303232 | F220: =IF(M220<>"",VLOOKUP(M220,zastavky!E:F,2,FALSE),"") | G220: +48 530 626 255 | H220: Rybnicka 31, Szczerbice, 44-293 | I220: 6 | J220: R | L220: 1
A221: 406 | B221: 5162 | C221: Dziacko | D221: Marta Magdalena | E221: 0004941641 | F221: =IF(M221<>"",VLOOKUP(M221,zastavky!E:F,2,FALSE),"") | G221: +48 731 070 755 | H221: 3 Maja 37, Jastrzebie Zdroj, 44-335 | I221: 6 | J221: R | L221: 1
A222: 407 | B222: 5164 | C222: Elišer | D222: Václav | E222: 0005010380 | F222: =IF(M222<>"",VLOOKUP(M222,zastavky!E:F,2,FALSE),"") | G222: +420 704 495 69 | H222: Československé armády 487, Frýdek-Místek, Místek, 738 01 | I222: 6 | J222: R | L222: 1
A223: 408 | B223: 62 | C223: Ferfecki | D223: Lukasz Wiktor | E223: 0004222254 | F223: =IF(M223<>"",VLOOKUP(M223,zastavky!E:F,2,FALSE),"") | G223: +48 799 074 575 | H223: Sw. Marcina 85, Ochaby Wielkie, 43430 | I223: 6 | J223: R | L223: 1
...
