Workbook

Sheet zastavky
A1: id | B1: spz | C1: oznaceni | D1: zastavka | E1: vyber
A2: 1 | B2: SK822SC SCANIA | C2: BATZ - Szeroka / Jastrzębie Zdrój / Wodzislaw Sl. | D2: 1 Szeroka ul. Rybnicka | E2: =B2 & " " & C2 & " " & D2 -> SK822SC SCANIA BATZ - Szeroka / Jastrzębie Zdrój / Wodzislaw Sl. 1 Szeroka ul. Rybnicka | F2: =A2 -> 1
A3: 2 | B3: SK822SC SCANIA | C3: BATZ - Szeroka / Jastrzębie Zdrój / Wodzislaw Sl. | D3: 2 Szeroka - Biedronka | E3: =B3 & " " & C3 & " " & D3 -> SK822SC SCANIA BATZ - Szeroka / Jastrzębie Zdrój / Wodzislaw Sl. 2 Szeroka - Biedronka | F3: =A3 -> 2
A4: 3 | B4: SK822SC SCANIA | C4: BATZ - Szeroka / Jastrzębie Zdrój / Wodzislaw Sl. | D4: 3 Szeroka - Wasbruck | E4: =B4 & " " & C4 & " " & D4 -> SK822SC SCANIA BATZ - Szeroka / Jastrzębie Zdrój / Wodzislaw Sl. 3 Szeroka - Wasbruck | F4: =A4 -> 3
A5: 4 | B5: SK822SC SCANIA | C5: BATZ - Szeroka / Jastrzębie Zdrój / Wodzislaw Sl. | D5: 4 Jastr.Zd. - Pszczyńska/Rybnicka | E5: =B5 & " " & C5 & " " & D5 -> SK822SC SCANIA BATZ - Szeroka / Jastrzębie Zdrój / Wodzislaw Sl. 4 Jastr.Zd. - Pszczyńska/Rybnicka | F5: =A5 -> 4
A6: 5 | B6: SPRINTER / OPEL | C6: BATZ - Źory / Cieszyn | D6: Źory - Sąd Rejonowy | E6: =B6 & " " & C6 & " " & D6 -> SPRINTER / OPEL BATZ - Źory / Cieszyn Źory - Sąd Rejonowy | F6: =A6 -> 5
A7: 6 | B7: SPRINTER / OPEL | C7: BATZ - Źory / Cieszyn | D7: Źory - Bajerowka | E7: =B7 & " " & C7 & " " & D7 -> SPRINTER / OPEL BATZ - Źory / Cieszyn Źory - Bajerowka | F7: =A7 -> 6
A8: 7 | B8: SPRINTER / OPEL | C8: BATZ - Źory / Cieszyn | D8: Ruptawa - Cisówka | E8: =B8 & " " & C8 & " " & D8 -> SPRINTER / OPEL BATZ - Źory / Cieszyn Ruptawa - Cisówka | F8: =A8 -> 7
A9: 9 | B9: SPRINTER / OPEL | C9: BATZ - Źory / Cieszyn | D9: Zebrzydowice Ośrodek Zdrowia | E9: =B9 & " " & C9 & " " & D9 -> SPRINTER / OPEL BATZ - Źory / Cieszyn Zebrzydowice Ośrodek Zdrowia | F9: =A9 -> 9
A10: 10 | B10: SPRINTER / OPEL | C10: BATZ - Źory / Cieszyn | D10: Zebrzydowice Rondo | E10: =B10 & " " & C10 & " " & D10 -> SPRINTER / OPEL BATZ - Źory / Cieszyn Zebrzydowice Rondo | F10: =A10 -> 10
A11: 11 | B11: SPRINTER / OPEL | C11: BATZ - Źory / Cieszyn | D11: Kończyce Małe | E11: =B11 & " " & C11 & " " & D11 -> SPRINTER / OPEL BATZ - Źory / Cieszyn Kończyce Małe | F11: =A11 -> 11
A12: 12 | B12: SPRINTER / OPEL | C12: BATZ - Źory / Cieszyn | D12: Hażlach za rondo Crab | E12: =B12 & " " & C12 & " " & D12 -> SPRINTER / OPEL BATZ - Źory / Cieszyn Hażlach za rondo Crab | F12: =A12 -> 12
A13: 13 | B13: SPRINTER / OPEL | C13: BATZ - Źory / Cieszyn | D13: Hażlach obok GASTROMANIA | E13: =B13 & " " & C13 & " " & D13 -> SPRINTER / OPEL BATZ - Źory / Cieszyn Hażlach obok GASTROMANIA | F13: =A13 -> 13
... A171: 171 | B171: Oles | C171: DSC | D171: Źory - Zegar, aleja Niepodległości | E171: =B171 & " " & C171 & " " & D171 -> Oles DSC Źory - Zegar, aleja Niepodległości | F171: =A171 -> 171

Sheet zamestnanci
A1: id | B1: os_cislo | C1: os.cislo 2 | D1: prijmeni | E1: jmeno | F1: rfid | G1: nastup | H1: telefon | I1: adresa | J1: firma | K1: smena | L1: nepritomnost | M1: aktivni | N1: zastavka | O1: cílová stanice
A2: 1 | B2: 4984 | C2: 1 | D2: Koblanski | E2: Daniel Roman | F2: 0001932486 | G2: =IF(N2<>"",VLOOKUP(N2,zastavky!E:F,2,FALSE),"") -> 21 | H2: 48661131885 | I2: Rzemieslnicza 16, Marklowice, 44-321 | J2: 1 | K2: R | M2: 1 | N2: SK822SC SCANIA BATZ - Szeroka / Jastrzębie Zdrój / Wodzislaw Sl. 10 Wodzisław Śląski stacja paliw Circle K/McDonalds | O2: KMJ | P2: ="update zamestnanci set os_cislo='" & C2 & "', rfid='" & F2 & "',cilova='" & O2 & "',nastup='" & G2 & "' where os_cislo='" & C2 & "';" -> update zamestnanci set os_cislo='1', rfid='0001932486',cilova='KMJ',nastup='21' where os_cislo='1';
A3: 2 | B3: 4832 | C3: 2 | D3: Plusa | E3: Jolanta Anastazja | F3: 0001812666 | G3: =IF(N3<>"",VLOOKUP(N3,zastavky!E:F,2,FALSE),"") -> 23 | H3: 48579875413 | I3: Wolnosci 106, Wodzislaw Slaski, 44-300 | J3: 1 | K3: R | M3: 1 | N3: SK822SC SCANIA BATZ - Szeroka / Jastrzębie Zdrój / Wodzislaw Sl. 12 Wodzisław Śląski ul. Bogumińska - Cmentarz, działki | O3: KMJ | P3: ="update zamestnanci set os_cislo='" & C3 & "', rfid='" & F3 & "',cilova='" & O3 & "',nastup='" & G3 & "' where os_cislo='" & C3 & "';" -> update zamestnanci set os_cislo='2', rfid='0001812666',cilova='KMJ',nastup='23' where os_cislo='2';
A4: 3 | B4: 4821 | C4: 3 | D4: Lapczyk | E4: Wiktoria Monika | F4: 0001203587 | G4: =IF(N4<>"",VLOOKUP(N4,zastavky!E:F,2,FALSE),"") -> 21 | H4: 48570354807 | I4: Stanislawa Moniuszki 24/57, Cieszyn, 43-400 | J4: 1 | K4: R | M4: 1 | N4: SK822SC SCANIA BATZ - Szeroka / Jastrzębie Zdrój / Wodzislaw Sl. 10 Wodzisław Śląski stacja paliw Circle K/McDonalds | O4: KMJ | P4: ="update zamestnanci set os_cislo='" & C4 & "', rfid='" & F4 & "',cilova='" & O4 & "',nastup='" & G4 & "' where os_cislo='" & C4 & "';" -> update zamestnanci set os_cislo='3', rfid='0001203587',cilova='KMJ',nastup='21' where os_cislo='3';
A5: 4 | B5: 4824 | C5: 4 | D5: Siemieniec | E5: Mirela Malgorzata | F5: 0001319249 | G5: =IF(N5<>"",VLOOKUP(N5,zastavky!E:F,2,FALSE),"") -> 26 | H5: 48534420008 | I5: Generala Sikorskiego 10, Gorzyce, 44-350 | J5: 1 | K5: R | M5: 1 | N5: SK822SC SCANIA BATZ - Szeroka / Jastrzębie Zdrój / Wodzislaw Sl. 15 UNIWAR | O5: KMJ | P5: ="update zamestnanci set os_cislo='" & C5 & "', rfid='" & F5 & "',cilova='" & O5 & "',nastup='" & G5 & "' where os_cislo='" & C5 & "';" -> update zamestnanci set os_cislo='4', rfid='0001319249',cilova='KMJ',nastup='26' where os_cislo='4';
A6: 5 | B6: 4816 | C6: 5 | D6: Tkocz | E6: Grazyna | F6: 0001348553 | G6: =IF(N6<>"",VLOOKUP(N6,zastavky!E:F,2,FALSE),"") -> 22 | H6: 48780473033 | I6: Rynek 19/4, Wodzislaw Slaski, 44-300 | J6: 1 | K6: R | M6: 1 | N6: SK822SC SCANIA BATZ - Szeroka / Jastrzębie Zdrój / Wodzislaw Sl. 11 Wodzisław Śląski Dworzec Autobus. Galeria Karuzela | O6: KMJ | P6: ="update zamestnanci set os_cislo='" & C6 & "', rfid='" & F6 & "',cilova='" & O6 & "',nastup='" & G6 & "' where os_cislo='" & C6 & "';" -> update zamestnanci set os_cislo='5', rfid='0001348553',cilova='KMJ',nastup='22' where os_cislo='5';
A7: 6 | B7: 4823 | C7: 6 | D7: Tomala | E7: Sabina Agata | F7: 0001213514 | G7: =IF(N7<>"",VLOOKUP(N7,zastavky!E:F,2,FALSE),"") -> 17 | H7: 48731071831 | I7: Truchana 36/12, Chorzow, 41-500 | J7: 1 | K7: R | M7: 1 | N7: SK822SC SCANIA BATZ - Szeroka / Jastrzębie Zdrój / Wodzislaw Sl. 6 Jastr.Zd. - Aleje Piłsudskiego SUPERSAM | O7: KMJ | P7: ="update zamestnanci set os_cislo='" & C7 & "', rfid='" & F7 & "',cilova='" & O7 & "',nastup='" & G7 & "' where os_cislo='" & C7 & "';" -> update zamestnanci set os_cislo='6', rfid='0001213514',cilova='KMJ',nastup='17' where os_cislo='6';
A8: 7 | B8: 5139 | C8: 7 | D8: Wisniewski | E8: Andrzej Jaroslaw | F8: 0001815983 | G8: =IF(N8<>"",VLOOKUP(N8,zastavky!E:F,2,FALSE),"") -> 21 | H8: 48577599086 | I8: Jana Kilinskiego 6, Marklowice, 44-321 | J8: 1 | K8: R | M8: 1 | N8: SK822SC SCANIA BATZ - Szeroka / Jastrzębie Zdrój / Wodzislaw Sl. 10 Wodzisław Śląski stacja paliw Circle K/McDonalds | O8: KMJ | P8: ="update zamestnanci set os_cislo='" & C8 & "', rfid='" & F8 & "',cilova='" & O8 & "',nastup='" & G8 & "' where os_cislo='" & C8 & "';" -> update zamestnanci set os_cislo='7', rfid='0001815983',cilova='KMJ',nastup='21' where os_cislo='7';
A9: 8 | B9: 4820 | C9: 8 | D9: Zdunek | E9: Patrycja | F9: 0003356249 | G9: =IF(N9<>"",VLOOKUP(N9,zastavky!E:F,2,FALSE),"") -> 100 | H9: 48535337339 | I9: Stanislawa Moniuszki 24/57, Cieszyn, 43-400 | J9: 1 | K9: R | M9: 1 | N9: Vlastní auto Zaměstnanci, co jezdí vlastní dopravou Vlastní auto | O9: KMJ | P9: ="update zamestnanci set os_cislo='" & C9 & "', rfid='" & F9 & "',cilova='" & O9 & "',nastup='" & G9 & "' where os_cislo='" & C9 & "';" -> update zamestnanci set os_cislo='8', rfid='0003356249',cilova='KMJ',nastup='100' where os_cislo='8';
A10: 29 | B10: 4617 | C10: 9 | D10: Karkoszka | E10: Justyna Agnieszka | F10: 0328432914 | G10: =IF(N10<>"",VLOOKUP(N10,zastavky!E:F,2,FALSE),"") -> 21 | H10: 48 576 673 042 | I10: Tysiaclecia 18/7, Wodzislaw Slaski, 44-300 | J10: 1 | K10: R | M10: 1 | N10: SK822SC SCANIA BATZ - Szeroka / Jastrzębie Zdrój / Wodzislaw Sl. 10 Wodzisław Śląski stacja paliw Circle K/McDonalds | O10: BATZ | P10: ="update zamestnanci set os_cislo='" & C10 & "', rfid='" & F10 & "',cilova='" & O10 & "',nastup='" & G10 & "' where os_cislo='" & C10 & "';" -> update zamestnanci set os_cislo='9', rfid='0328432914',cilova='BATZ',nastup='21' where os_cislo='9';
A11: 30 | B11: 5260 | C11: 10 | D11: Malec | E11: Julia Aleksandra | F11: 0328454862 | G11: =IF(N11<>"",VLOOKUP(N11,zastavky!E:F,2,FALSE),"") -> 17 | H11: 48 572 902 549 | I11: Malopolska 93/4, Jastrzebie-Zdrój, 44-335 | J11: 1 | K11: R | M11: 1 | N11: SK822SC SCANIA BATZ - Szeroka / Jastrzębie Zdrój / Wodzislaw Sl. 6 Jastr.Zd. - Aleje Piłsudskiego SUPERSAM | O11: BATZ | P11: ="update zamestnanci set os_cislo='" & C11 & "', rfid='" & F11 & "',cilova='" & O11 & "',nastup='" & G11 & "' where os_cislo='" & C11 & "';" -> update zamestnanci set os_cislo='10', rfid='0328454862',cilova='BATZ',nastup='17' where os_cislo='10';
A12: 31 | B12: 5129 | C12: 11 | D12: Buza | E12: Grazyna Aniela | F12: 0328432941 | G12: =IF(N12<>"",VLOOKUP(N12,zastavky!E:F,2,FALSE),"") -> 1 | H12: 48 788 217 740 | I12: Cicha 10, Gogolowa , 44-323 | J12: 1 | K12: R | M12: 1 | N12: SK822SC SCANIA BATZ - Szeroka / Jastrzębie Zdrój / Wodzislaw Sl. 1 Szeroka ul. Rybnicka | O12: BATZ | P12: ="update zamestnanci set os_cislo='" & C12 & "', rfid='" & F12 & "',cilova='" & O12 & "',nastup='" & G12 & "' where os_cislo='" & C12 & "';" -> update zamestnanci set os_cislo='11', rfid='0328432941',cilova='BATZ',nastup='1' where os_cislo='11';
A13: 32 | B13: 5275 | C13: 12 | D13: Pogoda | E13: Beata Anita | F13: 0348334221 | G13: =IF(N13<>"",VLOOKUP(N13,zastavky!E:F,2,FALSE),"") -> 21 | H13: 48 606 252 415 | I13: Rymera 247, Radlin, 44-310 | J13: 1 | K13: R | M13: 1 | N13: SK822SC SCANIA BATZ - Szeroka / Jastrzębie Zdrój / Wodzislaw Sl. 10 Wodzisław Śląski stacja paliw Circle K/McDonalds | O13: BATZ | P13: ="update zamestnanci set os_cislo='" & C13 & "', rfid='" & F13 & "',cilova='" & O13 & "',nastup='" & G13 & "' where os_cislo='" & C13 & "';" -> update zamestnanci set os_cislo='12', rfid='0348334221',cilova='BATZ',nastup='21' where os_cislo='12';
... A65: 90 | B65: 2069 | C65: 64 | D65: Debner | E65: Karolina | F65: 0301165689 | G65: =IF(N65<>"",VLOOKUP(N65,zastavky!E:F,2,FALSE),"") -> 17 | H65: 48 739 218 695 | I65: Promienna 5/201, Zory, 44-240 | J65: 1 | K65: R | M65: 1 | N65: SK822SC SCANIA BATZ - Szeroka / Jastrzębie Zdrój / Wodzislaw Sl. 6 Jastr.Zd. - Aleje Piłsudskiego SUPERSAM | O65: BATZ | P65: ="update zamestnanci set os_cislo='" & C65 & "', rfid='" & F65 & "',cilova='" & O65 & "',nastup='" & G65 & "' where os_cislo='" & C65 & "';" -> update zamestnanci set os_cislo='64', rfid='0301165689',cilova='BATZ',nastup='17' where os_cislo='64';
A66: 91 | B66: 2230 | C66: 65 | D66: Piechaczek | E66: Agnieszka | F66: 0272698616 | G66: =IF(N66<>"",VLOOKUP(N66,zastavky!E:F,2,FALSE),"") -> 19 | I66: Wiejska 21, Jastrzebie-Zdroj, 44-338 | J66: 1 | K66: R | M66: 1 | N66: SK822SC SCANIA BATZ - Szeroka / Jastrzębie Zdrój / Wodzislaw Sl. 8 Jastr.Zd. - Armii Krajowej | O66: BATZ | P66: ="update zamestnanci set os_cislo='" & C66 & "', rfid='" & F66 & "',cilova='" & O66 & "',nastup='" & G66 & "' where os_cislo='" & C66 & "';" -> update zamestnanci set os_cislo='65', rfid='0272698616',cilova='BATZ',nastup='19' where os_cislo='65';
A67: 92 | B67: 2945 | C67: 66 | D67: Francová | E67: Karolína | F67: 0289821261 | G67: =IF(N67<>"",VLOOKUP(N67,zastavky!E:F,2,FALSE),"") -> 27 | H67: 770 664 657 | I67: Hrnčířská 2003, Rožnov pod Radhoštěm, 756 61 | J67: 1 | K67: R | M67: 1 | N67: SK822SC SCANIA BATZ - Szeroka / Jastrzębie Zdrój / Wodzislaw Sl. 16 Ostrava Dřevoprodej | O67: BATZ | P67: ="update zamestnanci set os_cislo='" & C67 & "', rfid='" & F67 & "',cilova='" & O67 & "',nastup='" & G67 & "' where os_cislo='" & C67 & "';" -> update zamestnanci set os_cislo='66', rfid='0289821261',cilova='BATZ',nastup='27' where os_cislo='66';
A68: 93 | B68: 5175 | C68: 67 | D68: Wywiol | E68: Romeusz | F68: 0315321918 | G68: =IF(N68<>"",VLOOKUP(N68,zastavky!E:F,2,FALSE),"") -> 16 | H68: 48 574 677 081 | I68: Turystyczna 1, Jastrzebie-Zdrój, 44-335 | J68: 1 | K68: R | M68: 1 | N68: SK822SC SCANIA BATZ - Szeroka / Jastrzębie Zdrój / Wodzislaw Sl. 5 Jastr.Zd. - Al. Piłsudskiego - Os. Morcinka / Urząd Miasta | O68: BATZ | P68: ="update zamestnanci set os_cislo='" & C68 & "', rfid='" & F68 & "',cilova='" & O68 & "',nastup='" & G68 & "' where os_cislo='" & C68 & "';" -> update zamestnanci set os_cislo='67', rfid='0315321918',cilova='BATZ',nastup='16' where os_cislo='67';
A69: 94 | B69: 3257 | C69: 68 | D69: Starzyczny | E69: Joanna | F69: 0272698647 | G69: =IF(N69<>"",VLOOKUP(N69,zastavky!E:F,2,FALSE),"") -> 19 | H69: 48 693 474 209 | I69: Wiejska 9 A m.1, Jastrzebie-Zdrój, 44-338 | J69: 1 | K69: R | M69: 1 | N69: SK822SC SCANIA BATZ - Szeroka / Jastrzębie Zdrój / Wodzislaw Sl. 8 Jastr.Zd. - Armii Krajowej | O69: BATZ | P69: ="update zamestnanci set os_cislo='" & C69 & "', rfid='" & F69 & "',cilova='" & O69 & "',nastup='" & G69 & "' where os_cislo='" & C69 & "';" -> update zamestnanci set os_cislo='68', rfid='0272698647',cilova='BATZ',nastup='19' where os_cislo='68';
A70: 95 | B70: 3369 | C70: 69 | D70: Mottlová | E70: Markéta | F70: 0315321940 | G70: =IF(N70<>"",VLOOKUP(N70,zastavky!E:F,2,FALSE),"") -> 27 | H70: 720 578 148 | I70: Závodní 409/53, Ostrava - Hrabůvka, 700 30 | J70: 1 | K70: R | M70: 1 | N70: SK822SC SCANIA BATZ - Szeroka / Jastrzębie Zdrój / Wodzislaw Sl. 16 Ostrava Dřevoprodej | O70: BATZ | P70: ="update zamestnanci set os_cislo='" & C70 & "', rfid='" & F70 & "',cilova='" & O70 & "',nastup='" & G70 & "' where os_cislo='" & C70 & "';" -> update zamestnanci set os_cislo='69', rfid='0315321940',cilova='BATZ',nastup='27' where os_cislo='69';
A71: 96 | B71: 3078 | C71: 70 | D71: Niznik | E71: Boguslaw | F71: 0315321941 | G71: =IF(N71<>"",VLOOKUP(N71,zastavky!E:F,2,FALSE),"") -> 21 | I71: Dygasinskiego 33, Pszów, 44-370 | J71: 1 | K71: R | M71: 1 | N71: SK822SC SCANIA BATZ - Szeroka / Jastrzębie Zdrój / Wodzislaw Sl. 10 Wodzisław Śląski stacja paliw Circle K/McDonalds | O71: BATZ | P71: ="update zamestnanci set os_cislo='" & C71 & "', rfid='" & F71 & "',cilova='" & O71 & "',nastup='" & G71 & "' where os_cislo='" & C71 & "';" -> update zamestnanci set os_cislo='70', rfid='0315321941',cilova='BATZ',nastup='21' where os_cislo='70';
A72: 97 | B72: 3721 | C72: 71 | D72: Fitrzyková | E72: Jana | F72: 0328604658 | G72: =IF(N72<>"",VLOOKUP(N72,zastavky!E:F,2,FALSE),"") -> 27 | H72: 704 188 141 | I72: Těšínská 87/281, Ostrava - Radvanice, 716 00 | J72: 1 | K72: R | M72: 1 | N72: SK822SC SCANIA BATZ - Szeroka / Jastrzębie Zdrój / Wodzislaw Sl. 16 Ostrava Dřevoprodej | O72: BATZ | P72: ="update zamestnanci set os_cislo='" & C72 & "', rfid='" & F72 & "',cilova='" & O72 & "',nastup='" & G72 & "' where os_cislo='" & C72 & "';" -> update zamestnanci set os_cislo='71', rfid='0328604658',cilova='BATZ',nastup='27' where os_cislo='71';
A73: 98 | B73: 3729 | C73: 72 | D73: Chodinský | E73: Jakub | F73: 0328608672 | G73: =IF(N73<>"",VLOOKUP(N73,zastavky!E:F,2,FALSE),"") -> 27 | H73: 735 997 947 | I73: Vyškovická 447/153 , Ostrava - Výškovice, 700 30 | J73: 1 | K73: R | M73: 1 | N73: SK822SC SCANIA BATZ - Szeroka / Jastrzębie Zdrój / Wodzislaw Sl. 16 Ostrava Dřevoprodej | O73: BATZ | P73: ="update zamestnanci set os_cislo='" & C73 & "', rfid='" & F73 & "',cilova='" & O73 & "',nastup='" & G73 & "' where os_cislo='" & C73 & "';" -> update zamestnanci set os_cislo='72', rfid='0328608672',cilova='BATZ',nastup='27' where os_cislo='72';
A74: 99 | B74: 3728 | C74: 73 | D74: Chodinský | E74: Rostislav | F74: 0301165667 | G74: =IF(N74<>"",VLOOKUP(N74,zastavky!E:F,2,FALSE),"") -> 27 | H74: 735 883 940 | I74: Vyškovická 447/153 , Ostrava - Výškovice, 700 30 | J74: 1 | K74: R | M74: 1 | N74: SK822SC SCANIA BATZ - Szeroka / Jastrzębie Zdrój / Wodzislaw Sl. 16 Ostrava Dřevoprodej | O74: BATZ | P74: ="update zamestnanci set os_cislo='" & C74 & "', rfid='" & F74 & "',cilova='" & O74 & "',nastup='" & G74 & "' where os_cislo='" & C74 & "';" -> update zamestnanci set os_cislo='73', rfid='0301165667',cilova='BATZ',nastup='27' where os_cislo='73';
A75: 100 | B75: 4365 | C75: 74 | D75: Šostá | E75: Ivana | F75: 0315325893 | G75: =IF(N75<>"",VLOOKUP(N75,zastavky!E:F,2,FALSE),"") -> 27 | H75: 702 897 627 | I75: Hulvácká 1399/11a, Ostrava-Zábřeh , 700 30 | J75: 1 | K75: R | M75: 1 | N75: SK822SC SCANIA BATZ - Szeroka / Jastrzębie Zdrój / Wodzislaw Sl. 16 Ostrava Dřevoprodej | O75: BATZ | P75: ="update zamestnanci set os_cislo='" & C75 & "', rfid='" & F75 & "',cilova='" & O75 & "',nastup='" & G75 & "' where os_cislo='" & C75 & "';" -> update zamestnanci set os_cislo='74', rfid='0315325893',cilova='BATZ',nastup='27' where os_cislo='74';
A76: 101 | B76: 3284 | C76: 75 | D76: Matuszczyk | E76: Beata | F76: 0328608668 | G76: =IF(N76<>"",VLOOKUP(N76,zastavky!E:F,2,FALSE),"") -> 20 | H76: 48 692 755 081 | I76: Górnicza 38/23, Jastrzebie-Zdroj, 44-335 | J76: 1 | K76: R | M76: 1 | N76: SK822SC SCANIA BATZ - Szeroka / Jastrzębie Zdrój / Wodzislaw Sl. 9 Mszana | O76: BATZ | P76: ="update zamestnanci set os_cislo='" & C76 & "', rfid='" & F76 & "',cilova='" & O76 & "',nastup='" & G76 & "' where os_cislo='" & C76 & "';" -> update zamestnanci set os_cislo='75', rfid='0328608668',cilova='BATZ',nastup='20' where os_cislo='75';
A77: 102 | B77: 4326 | C77: 76 | D77: Lázoková | E77: Darina | F77: 0328608677 | G77: =IF(N77<>"",VLOOKUP(N77,zastavky!E:F,2,FALSE),"") -> 28 | H77: 705 926 915 | I77: Lidická 539, Třinec - Lyžbice, 739 61 | J77: 1 | K77: R | M77: 1 | N77: SK822SC SCANIA BATZ - Szeroka / Jastrzębie Zdrój / Wodzislaw Sl. 17 Frýdek - Místek autobusová zastávka Benzina - KMJ | O77: BATZ | P77: ="update zamestnanci set os_cislo='" & C77 & "', rfid='" & F77 & "',cilova='" & O77 & "',nastup='" & G77 & "' where os_cislo='" & C77 & "';" -> update zamestnanci set os_cislo='76', rfid='0328608677',cilova='BATZ',nastup='28' where os_cislo='76';
A78: 103 | B78: 4442 | C78: 77 | D78: Pajor | E78: Artur | F78: 0301165649 | G78: =IF(N78<>"",VLOOKUP(N78,zastavky!E:F,2,FALSE),"") -> 20 | H78: 48 731 773 661 | I78: Gustawa Morcinka 8/6, Jastrzebie-Zdroj, 44-335 | J78: 1 | K78: R | M78: 1 | N78: SK822SC SCANIA BATZ - Szeroka / Jastrzębie Zdrój / Wodzislaw Sl. 9 Mszana | O78: BATZ | P78: ="update zamestnanci set os_cislo='" & C78 & "', rfid='" & F78 & "',cilova='" & O78 & "',nastup='" & G78 & "' where os_cislo='" & C78 & "';" -> update zamestnanci set os_cislo='77', rfid='0301165649',cilova='BATZ',nastup='20' where os_cislo='77';
A79: 104 | B79: 3871 | C79: 78 | D79: Neudert | E79: Pavel | F79: 0370053055 | G79: =IF(N79<>"",VLOOKUP(N79,zastavky!E:F,2,FALSE),"") -> 28 | H79: 704 717 533 | I79: Horní 791/3, Ostrava - Hrabůvka, 700 30 | J79: 1 | K79: R | M79: 1 | N79: SK822SC SCANIA BATZ - Szeroka / Jastrzębie Zdrój / Wodzislaw Sl. 17 Frýdek - Místek autobusová zastávka Benzina - KMJ | O79: BATZ | P79: ="update zamestnanci set os_cislo='" & C79 & "', rfid='" & F79 & "',cilova='" & O79 & "',nastup='" & G79 & "' where os_cislo='" & C79 & "';" -> update zamestnanci set os_cislo='78', rfid='0370053055',cilova='BATZ',nastup='28' where os_cislo='78';
A80: 105 | B80: 3920 | C80: 79 | D80: Krzenek | E80: Ryszarda | F80: 0315325856 | G80: =IF(N80<>"",VLOOKUP(N80,zastavky!E:F,2,FALSE),"") -> 14 | H80: 48 725 009 441 | I80: Skrajna 4 m.6, Cieszyn, 43-400 | J80: 1 | K80: R | M80: 1 | N80: SPRINTER / OPEL BATZ - Źory / Cieszyn Cieszyn McDonalds | O80: BATZ | P80: ="update zamestnanci set os_cislo='" & C80 & "', rfid='" & F80 & "',cilova='" & O80 & "',nastup='" & G80 & "' where os_cislo='" & C80 & "';" -> update zamestnanci set os_cislo='79', rfid='0315325856',cilova='BATZ',nastup='14' where os_cislo='79';
A81: 106 | B81: 4622 | C81: 80 | D81: Starosta | E81: Barbara | F81: 0328443818 | G81: =IF(N81<>"",VLOOKUP(N81,zastavky!E:F,2,FALSE),"") -> 21 | H81: 48 735 049 358 | I81: Radlinska 147, Wodzislaw Slaski, 44-300 | J81: 1 | K81: R | M81: 1 | N81: SK822SC SCANIA BATZ - Szeroka / Jastrzębie Zdrój / Wodzislaw Sl. 10 Wodzisław Śląski stacja paliw Circle K/McDonalds | O81: BATZ | P81: ="update zamestnanci set os_cislo='" & C81 & "', rfid='" & F81 & "',cilova='" & O81 & "',nastup='" & G81 & "' where os_cislo='" & C81 & "';" -> update zamestnanci set os_cislo='80', rfid='0328443818',cilova='BATZ',nastup='21' where os_cislo='80';
A82: 108 | B82: 4719 | C82: 81 | D82: Paczowski | E82: Michal | F82: 0328611446 | G82: =IF(N82<>"",VLOOKUP(N82,zastavky!E:F,2,FALSE),"") -> 5 | H82: 48 535 384 403 | I82: Turnawiec 9,Turnawiec, 28-506 | J82: 1 | K82: R | M82: 1 | N82: SPRINTER / OPEL BATZ - Źory / Cieszyn Źory - Sąd Rejonowy | O82: BATZ | P82: ="update zamestnanci set os_cislo='" & C82 & "', rfid='" & F82 & "',cilova='" & O82 & "',nastup='" & G82 & "' where os_cislo='" & C82 & "';" -> update zamestnanci set os_cislo='81', rfid='0328611446',cilova='BATZ',nastup='5' where os_cislo='81';
A83: 109 | B83: 2463 | C83: 82 | D83: Krensel | E83: Maria | F83: 0289910254 | G83: =IF(N83<>"",VLOOKUP(N83,zastavky!E:F,2,FALSE),"") -> 100 | H83: 48 888 278 520 | I83: Poprzeczna 16/8, Jastrzebie-Zdrój, 44-330 | J83: 1 | K83: R | M83: 1 | N83: Vlastní auto Zaměstnanci, co jezdí vlastní dopravou Vlastní auto | O83: BATZ | P83: ="update zamestnanci set os_cislo='" & C83 & "', rfid='" & F83 & "',cilova='" & O83 & "',nastup='" & G83 & "' where os_cislo='" & C83 & "';" -> update zamestnanci set os_cislo='82', rfid='0289910254',cilova='BATZ',nastup='100' where os_cislo='82';
... A149: 584 | B149: 5276 | C149: 148 | D149: Frackiewicz | E149: Mateusz Dawid | F149: 0348387302 | G149: =IF(N149<>"",VLOOKUP(N149,zastavky!E:F,2,FALSE),"") -> 127 | H149: +48 570 980 131 | I149: Os. Generala Sikorskiego 22 I/1, Zory, 44-240 | J149: 3 | K149: R | M149: 1 | N149: Pielasa TATRA 1 Niedobczyce - PKP | O149: TATRA | P149: ="update zamestnanci set os_cislo='" & C149 & "', rfid='" & F149 & "',cilova='" & O149 & "',nastup='" & G149 & "' where os_cislo='" & C149 & "';" -> update zamestnanci set os_cislo='148', rfid='0348387302',cilova='TATRA',nastup='127' where os_cislo='148';
A150: 585 | B150: 5228 | C150: 149 | D150: Galus | E150: Wojciech Jan | F150: 0357229219 | G150: =IF(N150<>"",VLOOKUP(N150,zastavky!E:F,2,FALSE),"") | H150: +48 784 259 034 | I150: Kaszubska 10/9, Jastrzebie Zdroj, 44-335 | J150: 3 | K150: R | M150: 1 | O150: TATRA | P150: ="update zamestnanci set os_cislo='" & C150 & "', rfid='" & F150 & "',cilova='" & O150 & "',nastup='" & G150 & "' where os_cislo='" & C150 & "';" -> update zamestnanci set os_cislo='149', rfid='0357229219',cilova='TATRA',nastup='' where os_cislo='149';
A151: 586 | B151: 5055 | C151: 150 | D151: Chmielewski | E151: Arkadiusz Antoni | F151: 0369911673 | G151: =IF(N151<>"",VLOOKUP(N151,zastavky!E:F,2,FALSE),"") -> 133 | H151: +48 574 635 493 | I151: 26 Marca 29/24, Wodzislaw Slaski, 44-300 | J151: 3 | K151: R | M151: 1 | N151: Pielasa TATRA 1 Wodzisław Śląski - PKP | O151: TATRA | P151: ="update zamestnanci set os_cislo='" & C151 & "', rfid='" & F151 & "',cilova='" & O151 & "',nastup='" & G151 & "' where os_cislo='" & C151 & "';" -> update zamestnanci set os_cislo='150', rfid='0369911673',cilova='TATRA',nastup='133' where os_cislo='150';
A152: 587 | B152: 4768 | C152: 151 | D152: Jacewicz | E152: Jakub Jacek | F152: 0369947420 | G152: =IF(N152<>"",VLOOKUP(N152,zastavky!E:F,2,FALSE),"") -> 113 | H152: +48 500 754 433 | I152: Mikołaja Witczaka 4c/7, Jastrzębie-Zdrój, 44-335 | J152: 3 | K152: R | M152: 1 | N152: Pielasa TATRA 1 Jastrzębie Zdroj - Czarny Rycerz | O152: TATRA | P152: ="update zamestnanci set os_cislo='" & C152 & "', rfid='" & F152 & "',cilova='" & O152 & "',nastup='" & G152 & "' where os_cislo='" & C152 & "';" -> update zamestnanci set os_cislo='151', rfid='0369947420',cilova='TATRA',nastup='113' where os_cislo='151';
A153: 588 | B153: 5113 | C153: 152 | D153: Janiczek | E153: Kamil Patryk | F153: 0369978365 | G153: =IF(N153<>"",VLOOKUP(N153,zastavky!E:F,2,FALSE),"") -> 29 | H153: +48 884 337 008 | I153: os. 1000-lecia 8/25, Jastrzebie Zdroj, 44-268 | J153: 3 | K153: R | M153: 1 | N153: Pielasa TATRA 1 Żory - Sąd | O153: TATRA | P153: ="update zamestnanci set os_cislo='" & C153 & "', rfid='" & F153 & "',cilova='" & O153 & "',nastup='" & G153 & "' where os_cislo='" & C153 & "';" -> update zamestnanci set os_cislo='152', rfid='0369978365',cilova='TATRA',nastup='29' where os_cislo='152';
A154: 589 | B154: 5227 | C154: 153 | D154: Jazdzewski | E154: Robert Lukasz | F154: 0357221234 | G154: =IF(N154<>"",VLOOKUP(N154,zastavky!E:F,2,FALSE),"") -> 31 | H154: +48 789 769 471 | I154: Os. 1000-Lecia 7/57, Jastrzebie Zdroj, 44-268 | J154: 3 | K154: R | M154: 1 | N154: Pielasa TATRA 1 Jastrzębie Zdroj - Szeroka | O154: TATRA | P154: ="update zamestnanci set os_cislo='" & C154 & "', rfid='" & F154 & "',cilova='" & O154 & "',nastup='" & G154 & "' where os_cislo='" & C154 & "';" -> update zamestnanci set os_cislo='153', rfid='0357221234',cilova='TATRA',nastup='31' where os_cislo='153';
A155: 590 | B155: 4680 | C155: 154 | D155: Kala | E155: Janusz Eryk | F155: 0000916535 | G155: =IF(N155<>"",VLOOKUP(N155,zastavky!E:F,2,FALSE),"") -> 29 | H155: +48 537 097 454 | I155: Boryńska 23, Zory, 44-244 | J155: 3 | K155: R | M155: 1 | N155: Pielasa TATRA 1 Żory - Sąd | O155: TATRA | P155: ="update zamestnanci set os_cislo='" & C155 & "', rfid='" & F155 & "',cilova='" & O155 & "',nastup='" & G155 & "' where os_cislo='" & C155 & "';" -> update zamestnanci set os_cislo='154', rfid='0000916535',cilova='TATRA',nastup='29' where os_cislo='154';
A156: 591 | B156: 4998 | C156: 155 | D156: Karkoszka | E156: Michal Ireneusz | G156: =IF(N156<>"",VLOOKUP(N156,zastavky!E:F,2,FALSE),"") -> 133 | H156: +48 609 723 587 | I156: 1000-lecia 18/7, Wodzislaw Slaski, 44-300 | J156: 3 | K156: R | M156: 1 | N156: Pielasa TATRA 1 Wodzisław Śląski - PKP | O156: TATRA | P156: ="update zamestnanci set os_cislo='" & C156 & "', rfid='" & F156 & "',cilova='" & O156 & "',nastup='" & G156 & "' where os_cislo='" & C156 & "';" -> update zamestnanci set os_cislo='155', rfid='',cilova='TATRA',nastup='133' where os_cislo='155';
...
